Workbook

Sheet Start Here
B2: CS-57 - Contribution Tracker
B3: Human-AI Data Annotation, Provenance & Dataset Evaluation Platform | Group CS-57 | Client: Hunter Xu
B5: The one rule
C6: After your pull request is merged into main, add ONE row to the 'Contribution Log' tab. That is the whole process. Every other tab fills itself in from those rows.
B8: What each tab is for
B9: Contribution Log | C9: The only tab you type into. One row per merged PR. Cream headers = you fill in; grey headers = filled in automatically, do not type in them.
B10: Dashboard | C10: Automatic. Who merged what, per week and in total; review health; the split across frontend / backend / AI.
B11: Jira Statistics | C11: Who owns which bundle, how much of the committed scope is done, workload per person, and every issue on the board matched to the story it serves. Fill in the nine Owner cells once; the rest is a snapshot of docs/Jira.csv plus live PR counts.
B12: Client Report | C12: Set a date range at the top and this becomes the numbers block for the Status Checking form and the weekly client meeting.
B13: Lists | C13: Reference data behind the dropdowns and the automatic columns. Only edit the Week 1 Monday date, and only once.
B15: When you finish a story
C16: Work through this before you ask for a review. If you cannot tick items 1 and 2, the story is not finished - which is fine, but log the PR with 'Story complete? = No'.
C17: 1. Open the story in user-stories.html and re-read its acceptance criteria - every numbered criterion, not the one you remember. This is what 'done' means for that story.
C18: 2. The checks pass: npm run typecheck and the test suite run clean in whatever you touched (story A2).
C19: 3. There is a test covering the behaviour you changed, not only the code you wrote.
C20: 4. Anything a teammate could not guess is written down - a change note, and a decision record if you chose between real alternatives.
C21: 5. Open the PR with the story ID in the title, e.g. 'C2 - task queue progress'.
C22: 6. Request review from someone who did not write the code (story A1), and move the SCRUM ticket to In Review.
C23: 7. Once it is merged: move the SCRUM ticket to Done, then add your row to the Contribution Log.
C24: 8. Set 'Story complete? = Yes' only if every acceptance criterion is now met. If it closed a catalogued defect, put the issue number in 'Defects closed'.
B26: How to log a merged PR
C27: 1. Open 'Contribution Log' and go to the first empty row.
C28: 2. Date merged - the date the PR landed on main. The Week column fills itself in from this.
C29: 3. Member is you. Reviewed by is the teammate who approved the PR. They must be different people (story A1 - no change reaches main without a second person's review); the sheet turns the row red if they are not.
C30: 4. Story ID - pick the backlog story the work serves (A1 ... K4). The story title, epic and priority appear automatically.
C31: 5. What changed - one sentence a non-engineer can understand. This sentence is what gets read out to the client, so write it for the client, not for the team.
C32: 6. Story complete? - answer 'Yes' only when nothing further is needed for that story. This is what drives every progress number in the workbook.
B34: What a good row looks like
C35: Date merged | D35: Member | E35: Reviewed by | F35: Work type | G35: Story ID | H35: What changed (plain English, for the client) | I35: Story complete?
C36: 2026-09-08 | D36: Hanchen Wang | E36: Michael Max | F36: Feature | G36: C2 | H36: A task with 1,000 items now runs in the background and shows a live progress bar, instead of freezing the page. | I36: No - more work to come
C37: 2026-09-09 | D37: Yi Geng | E37: Dishank Aswal | F37: Defect fix | G37: C3 | H37: When the AI is unavailable the item is now marked 'AI failed' instead of being filled with an invented bounding box. | I37: Yes - story complete
C38: 2026-09-10 | D38: Parth | E38: Tok Tin Chung | F38: Client / PM / Report | G38: K2 | H38: Wrote up the Week 6 status report and the client's decision on dispute routing. | I38: N/A - not story work
C39: Note what the summaries do not say: no file names, no function names, no ticket jargon. Write the sentence the client would understand if it were read out loud.
B41: Ground rules
C42: - One row per merged PR - not per commit, and not per day of work.
C43: - Log it the same day it merges. A log reconstructed from memory in Week 12 is worth very little to anyone, including you.
C44: - Never delete or reorder someone else's row. If a row is wrong, correct that row.
C45: - Do not insert, delete or reorder columns. The other tabs read this one by column position and will break.
C46: - Work that is not a PR still counts - client meetings, the report, the proposal, research spikes. Log it with work type 'Client / PM / Report' or 'Spike / Research' and leave the PR number blank.
C47: - If one PR serves two stories, log the row against the main story and name the second one in Notes.

Sheet Contribution Log
A1: Date | B1: Week | C1: Member | D1: Reviewed by | E1: Review OK? | F1: SCRUM ticket | G1: PR # | H1: PR link | I1: Work type | J1: Area / repo | K1: Story ID | L1: Story title | M1: Epic | N1: Pri | O1: Defects closed | P1: What changed (plain English, for the client) | Q1: Story complete? | R1: Notes / evidence
A2: 46262 | B2: =IF(A2="","",IFERROR(LOOKUP(A2,Lists!$U$2:$U$14,Lists!$T$2:$T$14),"")) -> W4 | C2: Yi Geng | D2: Yi Geng | E2: =IF(OR(C2="",D2=""),"",IF(C2=D2,"SELF-REVIEW","OK")) -> SELF-REVIEW | G2: 1 | H2: https://github.com/USYD-CS-Capstone/hej/pull/1 | I2: Refactor | J2: Other | K2: - | L2: =IFERROR(IF(K2="","",VLOOKUP(K2,Lists!$K$2:$O$61,5,FALSE)),"") -> (not tied to a backlog story) | M2: =IFERROR(IF(K2="","",VLOOKUP(K2,Lists!$K$2:$O$61,2,FALSE)),"") | N2: =IFERROR(IF(K2="","",VLOOKUP(K2,Lists!$K$2:$O$61,3,FALSE)),"") | P2: Copy the branch name 'week13' (previous team's latest progress) to the main branch | Q2: N/A - not story work
A3: 46272 | B3: =IF(A3="","",IFERROR(LOOKUP(A3,Lists!$U$2:$U$14,Lists!$T$2:$T$14),"")) -> W6 | C3: Hanchen Wang | D3: Jingwei Lin | E3: =IF(OR(C3="",D3=""),"",IF(C3=D3,"SELF-REVIEW","OK")) -> OK | F3: SCRUM-82 | G3: 2 | H3: https://github.com/USYD-CS-Capstone/hej/pull/2 | I3: DevOps / CI | J3: CI / tooling | K3: A2 | L3: =IFERROR(IF(K3="","",VLOOKUP(K3,Lists!$K$2:$O$61,5,FALSE)),"") -> I can trust that a fix in one place hasn't broken another | M3: =IFERROR(IF(K3="","",VLOOKUP(K3,Lists!$K$2:$O$61,2,FALSE)),"") -> A | N3: =IFERROR(IF(K3="","",VLOOKUP(K3,Lists!$K$2:$O$61,3,FALSE)),"") -> P0 | O3: 12,13,25,26 | P3: Enable existing testing scripts, so changes can be verified before merging again. | Q3: Yes - story complete
A4: 46272 | B4: =IF(A4="","",IFERROR(LOOKUP(A4,Lists!$U$2:$U$14,Lists!$T$2:$T$14),"")) -> W6 | C4: Jingwei Lin | D4: Hanchen Wang | E4: =IF(OR(C4="",D4=""),"",IF(C4=D4,"SELF-REVIEW","OK")) -> OK | F4: SCRUM-44 | G4: 4 | H4: https://github.com/USYD-CS-Capstone/hej/pull/4 | I4: Feature | J4: hej-api (backend) | K4: G1 | L4: =IFERROR(IF(K4="","",VLOOKUP(K4,Lists!$K$2:$O$61,5,FALSE)),"") -> My role determines what I can do | M4: =IFERROR(IF(K4="","",VLOOKUP(K4,Lists!$K$2:$O$61,2,FALSE)),"") -> G | N4: =IFERROR(IF(K4="","",VLOOKUP(K4,Lists!$K$2:$O$61,3,FALSE)),"") -> P0 | O4: 7 | P4: Users now can only perform actions that the role allowed them to do. | Q4: Yes - story complete
A5: 46277 | B5: =IF(A5="","",IFERROR(LOOKUP(A5,Lists!$U$2:$U$14,Lists!$T$2:$T$14),"")) -> W6 | C5: Jingwei Lin | D5: Hanchen Wang | E5: =IF(OR(C5="",D5=""),"",IF(C5=D5,"SELF-REVIEW","OK")) -> OK | F5: SCRUM-29 | G5: 6 | H5: https://github.com/USYD-CS-Capstone/hej/pull/6 | I5: Defect fix | J5: hej-api (backend) | K5: D2 | L5: =IFERROR(IF(K5="","",VLOOKUP(K5,Lists!$K$2:$O$61,5,FALSE)),"") -> Approval history can't be rewritten behind my back | M5: =IFERROR(IF(K5="","",VLOOKUP(K5,Lists!$K$2:$O$61,2,FALSE)),"") -> D | N5: =IFERROR(IF(K5="","",VLOOKUP(K5,Lists!$K$2:$O$61,3,FALSE)),"") -> P0 | O5: 8 | P5: Retires the legacy review mutation endpoints that allowed approval history to be changed or deleted without updating the corresponding task-item state. | Q5: Yes - story complete
A6: 46277 | B6: =IF(A6="","",IFERROR(LOOKUP(A6,Lists!$U$2:$U$14,Lists!$T$2:$T$14),"")) -> W6 | C6: Michael Max | D6: Yi Geng | E6: =IF(OR(C6="",D6=""),"",IF(C6=D6,"SELF-REVIEW","OK")) -> OK | F6: SCRUM-30 | G6: 7 | H6: https://github.com/USYD-CS-Capstone/hej/pull/7 | I6: Defect fix | J6: hej-web (frontend) | K6: C3 | L6: =IFERROR(IF(K6="","",VLOOKUP(K6,Lists!$K$2:$O$61,5,FALSE)),"") -> I'm told when the AI failed instead of being shown a fake answer | M6: =IFERROR(IF(K6="","",VLOOKUP(K6,Lists!$K$2:$O$61,2,FALSE)),"") -> C | N6: =IFERROR(IF(K6="","",VLOOKUP(K6,Lists!$K$2:$O$61,3,FALSE)),"") -> P0 | O6: 20 | P6: With SCRUM-7; ... | Q6: Yes - story complete
A7: 46277 | B7: =IF(A7="","",IFERROR(LOOKUP(A7,Lists!$U$2:$U$14,Lists!$T$2:$T$14),"")) -> W6 | C7: Michael Max | D7: Yi Geng | E7: =IF(OR(C7="",D7=""),"",IF(C7=D7,"SELF-REVIEW","OK")) -> OK | F7: SCRUM-6 | G7: 8 | H7: https://github.com/USYD-CS-Capstone/hej/pull/8 | I7: Feature | J7: labeling_ai_assistnat_mvp (AI) | K7: C1 | L7: =IFERROR(IF(K7="","",VLOOKUP(K7,Lists!$K$2:$O$61,5,FALSE)),"") -> The AI assistant can be swapped without disrupting my work | M7: =IFERROR(IF(K7="","",VLOOKUP(K7,Lists!$K$2:$O$61,2,FALSE)),"") -> C | N7: =IFERROR(IF(K7="","",VLOOKUP(K7,Lists!$K$2:$O$61,3,FALSE)),"") -> P1 | O7: - | Q7: No - more work to come
A8: 46277 | B8: =IF(A8="","",IFERROR(LOOKUP(A8,Lists!$U$2:$U$14,Lists!$T$2:$T$14),"")) -> W6 | C8: Dishank Aswal | D8: Jingwei Lin | E8: =IF(OR(C8="",D8=""),"",IF(C8=D8,"SELF-REVIEW","OK")) -> OK | F8: SCRUM-22 | G8: 9 | H8: https://github.com/USYD-CS-Capstone/hej/pull/9 | I8: Defect fix | J8: hej-api (backend) | K8: G4 | L8: =IFERROR(IF(K8="","",VLOOKUP(K8,Lists!$K$2:$O$61,5,FALSE)),"") -> The platform refuses states that can't exist | M8: =IFERROR(IF(K8="","",VLOOKUP(K8,Lists!$K$2:$O$61,2,FALSE)),"") -> G | N8: =IFERROR(IF(K8="","",VLOOKUP(K8,Lists!$K$2:$O$61,3,FALSE)),"") -> P1 | O8: 10 | P8: Fixed task status validation and updated the allowed final statuses. | Q8: Yes - story complete
A9: 46277 | B9: =IF(A9="","",IFERROR(LOOKUP(A9,Lists!$U$2:$U$14,Lists!$T$2:$T$14),"")) -> W6 | C9: Dishank Aswal | D9: Jingwei Lin | E9: =IF(OR(C9="",D9=""),"",IF(C9=D9,"SELF-REVIEW","OK")) -> OK | F9: SCRUM-23 | G9: 9 | H9: https://github.com/USYD-CS-Capstone/hej/pull/9 | I9: Refactor | J9: hej-api (backend) | K9: B5 | L9: =IFERROR(IF(K9="","",VLOOKUP(K9,Lists!$K$2:$O$61,5,FALSE)),"") -> Loading a dataset either works or leaves nothing behind | M9: =IFERROR(IF(K9="","",VLOOKUP(K9,Lists!$K$2:$O$61,2,FALSE)),"") -> B | N9: =IFERROR(IF(K9="","",VLOOKUP(K9,Lists!$K$2:$O$61,3,FALSE)),"") -> P0 | O9: 29 | P9: Preserved task lifecycle conflict responses as HTTP 409 instead of returning 500 errors. | Q9: Yes - story complete
A10: 46277 | B10: =IF(A10="","",IFERROR(LOOKUP(A10,Lists!$U$2:$U$14,Lists!$T$2:$T$14),"")) -> W6 | C10: Michael Max | D10: Yi Geng | E10: =IF(OR(C10="",D10=""),"",IF(C10=D10,"SELF-REVIEW","OK")) -> OK | F10: SCRUM-81 | G10: 10 | H10: https://github.com/USYD-CS-Capstone/hej/pull/10 | I10: Defect fix | J10: hej-api (backend) | K10: A3 | L10: =IFERROR(IF(K10="","",VLOOKUP(K10,Lists!$K$2:$O$61,5,FALSE)),"") -> I can get a working copy of the platform running by myself | M10: =IFERROR(IF(K10="","",VLOOKUP(K10,Lists!$K$2:$O$61,2,FALSE)),"") -> A | N10: =IFERROR(IF(K10="","",VLOOKUP(K10,Lists!$K$2:$O$61,3,FALSE)),"") -> P0 | O10: 23, 24 | P10: With SCRUM-84; ... | Q10: No - more work to come
A11: 46277 | B11: =IF(A11="","",IFERROR(LOOKUP(A11,Lists!$U$2:$U$14,Lists!$T$2:$T$14),"")) -> W6 | C11: Kanishka Kathait | D11: Jingwei Lin | E11: =IF(OR(C11="",D11=""),"",IF(C11=D11,"SELF-REVIEW","OK")) -> OK | F11: SCRUM-34 | G11: 11 | H11: https://github.com/USYD-CS-Capstone/hej/pull/11 | I11: Defect fix | J11: hej-api (backend) | K11: B5 | L11: =IFERROR(IF(K11="","",VLOOKUP(K11,Lists!$K$2:$O$61,5,FALSE)),"") -> Loading a dataset either works or leaves nothing behind | M11: =IFERROR(IF(K11="","",VLOOKUP(K11,Lists!$K$2:$O$61,2,FALSE)),"") -> B | N11: =IFERROR(IF(K11="","",VLOOKUP(K11,Lists!$K$2:$O$61,3,FALSE)),"") -> P0 | O11: 16 | P11: Made dataset registration transactional to prevent partial data when AI fails. Added success and rollback tests. | Q11: No - more work to come
A12: 46277 | B12: =IF(A12="","",IFERROR(LOOKUP(A12,Lists!$U$2:$U$14,Lists!$T$2:$T$14),"")) -> W6 | C12: Hanchen Wang | D12: Yi Geng | E12: =IF(OR(C12="",D12=""),"",IF(C12=D12,"SELF-REVIEW","OK")) -> OK | F12: SCRUM-25 | G12: 13 | H12: https://github.com/USYD-CS-Capstone/hej/pull/13 | I12: Defect fix | J12: hej-web (frontend) | K12: D6 | L12: =IFERROR(IF(K12="","",VLOOKUP(K12,Lists!$K$2:$O$61,5,FALSE)),"") -> My unfinished work is mine | M12: =IFERROR(IF(K12="","",VLOOKUP(K12,Lists!$K$2:$O$61,2,FALSE)),"") -> D | N12: =IFERROR(IF(K12="","",VLOOKUP(K12,Lists!$K$2:$O$61,3,FALSE)),"") -> P0 | O12: 6 | P12: Enfored draft ownership (1 item - 1 annotator) unfinished draft belongs to its author, otherwise read-only. | Q12: Yes - story complete
A13: 46278 | B13: =IF(A13="","",IFERROR(LOOKUP(A13,Lists!$U$2:$U$14,Lists!$T$2:$T$14),"")) -> W6 | C13: Jingwei Lin | D13: Michael Max | E13: =IF(OR(C13="",D13=""),"",IF(C13=D13,"SELF-REVIEW","OK")) -> OK | F13: SCRUM-21 | G13: 14 | H13: https://github.com/USYD-CS-Capstone/hej/pull/14 | I13: Defect fix | J13: hej-api (backend) | K13: G3 | L13: =IFERROR(IF(K13="","",VLOOKUP(K13,Lists!$K$2:$O$61,5,FALSE)),"") -> My work stays inside my project | M13: =IFERROR(IF(K13="","",VLOOKUP(K13,Lists!$K$2:$O$61,2,FALSE)),"") -> G | N13: =IFERROR(IF(K13="","",VLOOKUP(K13,Lists!$K$2:$O$61,3,FALSE)),"") -> P0 | O13: 9 | P13: Enforce project boundaries on task writes | Q13: Yes - story complete
A14: 46279 | B14: =IF(A14="","",IFERROR(LOOKUP(A14,Lists!$U$2:$U$14,Lists!$T$2:$T$14),"")) -> W7 | C14: Tim Chung | D14: Jingwei Lin | E14: =IF(OR(C14="",D14=""),"",IF(C14=D14,"SELF-REVIEW","OK")) -> OK | F14: SCRUM-8 | G14: 16 | H14: https://github.com/USYD-CS-Capstone/hej/pull/16 | I14: Feature | J14: hej-api (backend) | K14: G5 | L14: =IFERROR(IF(K14="","",VLOOKUP(K14,Lists!$K$2:$O$61,5,FALSE)),"") -> I can actually invite someone into my organisation | M14: =IFERROR(IF(K14="","",VLOOKUP(K14,Lists!$K$2:$O$61,2,FALSE)),"") -> G | N14: =IFERROR(IF(K14="","",VLOOKUP(K14,Lists!$K$2:$O$61,3,FALSE)),"") -> P0 | O14: 17, 18 | P14: Backend only: registered users can be invited to an organisation and accept invitations successfully. | Q14: N/A - not story work
A15: 46279 | B15: =IF(A15="","",IFERROR(LOOKUP(A15,Lists!$U$2:$U$14,Lists!$T$2:$T$14),"")) -> W7 | C15: Parth | D15: Dishank Aswal | E15: =IF(OR(C15="",D15=""),"",IF(C15=D15,"SELF-REVIEW","OK")) -> OK | F15: SCRUM-35 | G15: 17 | H15: https://github.com/USYD-CS-Capstone/hej/pull/17 | I15: Defect fix | J15: hej-web (frontend) | K15: E2 | L15: =IFERROR(IF(K15="","",VLOOKUP(K15,Lists!$K$2:$O$61,5,FALSE)),"") -> I can send an item back to the annotator | M15: =IFERROR(IF(K15="","",VLOOKUP(K15,Lists!$K$2:$O$61,2,FALSE)),"") -> E | N15: =IFERROR(IF(K15="","",VLOOKUP(K15,Lists!$K$2:$O$61,3,FALSE)),"") -> P0 | O15: 15 | P15: User can send an item back to the annotator | Q15: Yes - story complete
A16: 46279 | B16: =IF(A16="","",IFERROR(LOOKUP(A16,Lists!$U$2:$U$14,Lists!$T$2:$T$14),"")) -> W7 | C16: Parth | D16: Dishank Aswal | E16: =IF(OR(C16="",D16=""),"",IF(C16=D16,"SELF-REVIEW","OK")) -> OK | F16: SCRUM-31 | G16: 17 | H16: https://github.com/USYD-CS-Capstone/hej/pull/17 | I16: Feature | J16: hej-api (backend) | K16: C5 | L16: =IFERROR(IF(K16="","",VLOOKUP(K16,Lists!$K$2:$O$61,5,FALSE)),"") -> I can record why I decided, not just what I decided | M16: =IFERROR(IF(K16="","",VLOOKUP(K16,Lists!$K$2:$O$61,2,FALSE)),"") -> C | N16: =IFERROR(IF(K16="","",VLOOKUP(K16,Lists!$K$2:$O$61,3,FALSE)),"") -> P1 | O16: - | P16: I can record why I decided, not just what I decided | Q16: Yes - story complete
A17: 46279 | B17: =IF(A17="","",IFERROR(LOOKUP(A17,Lists!$U$2:$U$14,Lists!$T$2:$T$14),"")) -> W7 | C17: Parth | D17: Dishank Aswal | E17: =IF(OR(C17="",D17=""),"",IF(C17=D17,"SELF-REVIEW","OK")) -> OK | G17: 17 | H17: https://github.com/USYD-CS-Capstone/hej/pull/17 | I17: Feature | J17: CI / tooling | K17: - | L17: =IFERROR(IF(K17="","",VLOOKUP(K17,Lists!$K$2:$O$61,5,FALSE)),"") -> (not tied to a backlog story) | M17: =IFERROR(IF(K17="","",VLOOKUP(K17,Lists!$K$2:$O$61,2,FALSE)),"") | N17: =IFERROR(IF(K17="","",VLOOKUP(K17,Lists!$K$2:$O$61,3,FALSE)),"") | O17: - | P17: Dockerize the application | Q17: N/A - not story work
A18: 46279 | B18: =IF(A18="","",IFERROR(LOOKUP(A18,Lists!$U$2:$U$14,Lists!$T$2:$T$14),"")) -> W7 | C18: Michael Max | D18: Yi Geng | E18: =IF(OR(C18="",D18=""),"",IF(C18=D18,"SELF-REVIEW","OK")) -> OK | F18: SCRUM-81 | G18: 18 | H18: https://github.com/USYD-CS-Capstone/hej/pull/18 | I18: Defect fix | J18: hej-api (backend) | K18: A3 | L18: =IFERROR(IF(K18="","",VLOOKUP(K18,Lists!$K$2:$O$61,5,FALSE)),"") -> I can get a working copy of the platform running by myself | M18: =IFERROR(IF(K18="","",VLOOKUP(K18,Lists!$K$2:$O$61,2,FALSE)),"") -> A | N18: =IFERROR(IF(K18="","",VLOOKUP(K18,Lists!$K$2:$O$61,3,FALSE)),"") -> P0 | O18: 23, 24 | Q18: No - more work to come
A19: 46281 | B19: =IF(A19="","",IFERROR(LOOKUP(A19,Lists!$U$2:$U$14,Lists!$T$2:$T$14),"")) -> W7 | C19: Hanchen Wang | D19: Dishank Aswal | E19: =IF(OR(C19="",D19=""),"",IF(C19=D19,"SELF-REVIEW","OK")) -> OK | F19: SCRUM-28 | G19: 19 | H19: https://github.com/USYD-CS-Capstone/hej/pull/19 | I19: Defect fix | J19: hej-api (backend) | K19: D5 | L19: =IFERROR(IF(K19="","",VLOOKUP(K19,Lists!$K$2:$O$61,5,FALSE)),"") -> Finalised means finalised | M19: =IFERROR(IF(K19="","",VLOOKUP(K19,Lists!$K$2:$O$61,2,FALSE)),"") -> D | N19: =IFERROR(IF(K19="","",VLOOKUP(K19,Lists!$K$2:$O$61,3,FALSE)),"") -> P0 | O19: 2 | P19: A finalised task item will not be mistakenly overwritten. | Q19: No - more work to come
A20: 46282 | B20: =IF(A20="","",IFERROR(LOOKUP(A20,Lists!$U$2:$U$14,Lists!$T$2:$T$14),"")) -> W7 | C20: Michael Max | D20: Hanchen Wang | E20: =IF(OR(C20="",D20=""),"",IF(C20=D20,"SELF-REVIEW","OK")) -> OK | F20: SCRUM-2 | G20: 20 | H20: https://github.com/USYD-CS-Capstone/hej/pull/20 | I20: Documentation | J20: Docs / report | K20: C2 | L20: =IFERROR(IF(K20="","",VLOOKUP(K20,Lists!$K$2:$O$61,5,FALSE)),"") -> A large batch of items gets AI-annotated reliably | M20: =IFERROR(IF(K20="","",VLOOKUP(K20,Lists!$K$2:$O$61,2,FALSE)),"") -> C | N20: =IFERROR(IF(K20="","",VLOOKUP(K20,Lists!$K$2:$O$61,3,FALSE)),"") -> P0 | O20: - | P20: Two proposal design docs for story C2 | Q20: No - more work to come
A21: 46282 | B21: =IF(A21="","",IFERROR(LOOKUP(A21,Lists!$U$2:$U$14,Lists!$T$2:$T$14),"")) -> W7 | C21: Michael Max | D21: Hanchen Wang | E21: =IF(OR(C21="",D21=""),"",IF(C21=D21,"SELF-REVIEW","OK")) -> OK | F21: SCRUM-1 | G21: 21 | H21: https://github.com/USYD-CS-Capstone/hej/pull/21 | I21: Feature | J21: Database / schema | K21: C2 | L21: =IFERROR(IF(K21="","",VLOOKUP(K21,Lists!$K$2:$O$61,5,FALSE)),"") -> A large batch of items gets AI-annotated reliably | M21: =IFERROR(IF(K21="","",VLOOKUP(K21,Lists!$K$2:$O$61,2,FALSE)),"") -> C | N21: =IFERROR(IF(K21="","",VLOOKUP(K21,Lists!$K$2:$O$61,3,FALSE)),"") -> P0 | O21: - | P21: Adds the two tables designed in #20: ai_batch_jobs and ai_item_jobs | Q21: No - more work to come
A22: 46283 | B22: =IF(A22="","",IFERROR(LOOKUP(A22,Lists!$U$2:$U$14,Lists!$T$2:$T$14),"")) -> W7 | C22: Michael Max | D22: Hanchen Wang | E22: =IF(OR(C22="",D22=""),"",IF(C22=D22,"SELF-REVIEW","OK")) -> OK | F22: SCRUM-2 | G22: 22 | H22: https://github.com/USYD-CS-Capstone/hej/pull/22 | I22: Feature | J22: hej-api (backend) | K22: C2 | L22: =IFERROR(IF(K22="","",VLOOKUP(K22,Lists!$K$2:$O$61,5,FALSE)),"") -> A large batch of items gets AI-annotated reliably | M22: =IFERROR(IF(K22="","",VLOOKUP(K22,Lists!$K$2:$O$61,2,FALSE)),"") -> C | N22: =IFERROR(IF(K22="","",VLOOKUP(K22,Lists!$K$2:$O$61,3,FALSE)),"") -> P0 | O22: - | P22: Moves the AI model call out of the dataset-registration request and into a worker process | Q22: No - more work to come
A23: 46284 | B23: =IF(A23="","",IFERROR(LOOKUP(A23,Lists!$U$2:$U$14,Lists!$T$2:$T$14),"")) -> W7 | C23: Hanchen Wang | D23: Kanishka Kathait | E23: =IF(OR(C23="",D23=""),"",IF(C23=D23,"SELF-REVIEW","OK")) -> OK | F23: SCRUM-26 | G23: 23 | H23: https://github.com/USYD-CS-Capstone/hej/pull/23 | I23: Defect fix | J23: hej-api (backend) | K23: D5 | L23: =IFERROR(IF(K23="","",VLOOKUP(K23,Lists!$K$2:$O$61,5,FALSE)),"") -> Finalised means finalised | M23: =IFERROR(IF(K23="","",VLOOKUP(K23,Lists!$K$2:$O$61,2,FALSE)),"") -> D | N23: =IFERROR(IF(K23="","",VLOOKUP(K23,Lists!$K$2:$O$61,3,FALSE)),"") -> P0 | O23: 11 | P23: Make draft submission atomic; a transaction is all or nothing. | Q23: No - more work to come
A24: 46285 | B24: W7 | C24: Parth | D24: Hanchen Wang | E24: =IF(OR(C24="",D24=""),"",IF(C24=D24,"SELF-REVIEW","OK")) -> OK | F24: SCRUM-94 | G24: 24 | H24: https://github.com/USYD-CS-Capstone/hej/pull/24 | I24: DevOps / CI | J24: Database / schema | K24: C2 | L24: Infrastructure: run on PostgreSQL while keeping SQLite working | M24: A | N24: =IFERROR(IF(K24="","",VLOOKUP(K24,Lists!$K$2:$O$61,3,FALSE)),"") -> P0 | O24: - | P24: PostgreSQL is now the default database for native and Docker development. SQLite can still be selected explicitly through DATABASE_URL | Q24: No - more work to come | R24: Co-reviewed with Yi Geng.
A25: 46285 | B25: =IF(A25="","",IFERROR(LOOKUP(A25,Lists!$U$2:$U$14,Lists!$T$2:$T$14),"")) -> W7 | C25: Jingwei Lin | D25: Parth | E25: =IF(OR(C25="",D25=""),"",IF(C25=D25,"SELF-REVIEW","OK")) -> OK | F25: SCRUM-20 | G25: 25 | H25: https://github.com/USYD-CS-Capstone/hej/pull/25 | I25: Feature | J25: hej-web (frontend) | K25: B2 | L25: =IFERROR(IF(K25="","",VLOOKUP(K25,Lists!$K$2:$O$61,5,FALSE)),"") -> I can decide how carefully my project's work gets reviewed | M25: D | N25: =IFERROR(IF(K25="","",VLOOKUP(K25,Lists!$K$2:$O$61,3,FALSE)),"") -> P0 | O25: - | P25: Adds a project-level review and annotation policy layer between organisation defaults and task overrides. | Q25: No - more work to come
A26: 46285 | B26: =IF(A26="","",IFERROR(LOOKUP(A26,Lists!$U$2:$U$14,Lists!$T$2:$T$14),"")) -> W7 | C26: Dishank Aswal | D26: Kanishka Kathait | E26: =IF(OR(C26="",D26=""),"",IF(C26=D26,"SELF-REVIEW","OK")) -> OK | F26: SCRUM-43 | G26: 26 | H26: https://github.com/USYD-CS-Capstone/hej/pull/26 | I26: Defect fix | J26: hej-api (backend) | K26: B6 | L26: =IFERROR(IF(K26="","",VLOOKUP(K26,Lists!$K$2:$O$61,5,FALSE)),"") -> “Done” means the same thing everywhere I look | M26: B | N26: =IFERROR(IF(K26="","",VLOOKUP(K26,Lists!$K$2:$O$61,3,FALSE)),"") -> P1 | O26: 14, 19, 27 | P26: Aligned task completion and export rules so only canonicalized items are treated as final and eligible for export. Centralised the eligibility check and updated the related tests. | Q26: Yes - story complete
A27: 46285 | B27: W7 | C27: Yi Geng | D27: Jingwei Lin | E27: =IF(OR(C27="",D27=""),"",IF(C27=D27,"SELF-REVIEW","OK")) -> OK | F27: SCRUM-6 | G27: 27 | H27: https://github.com/USYD-CS-Capstone/hej/pull/27 | I27: Feature | J27: hej-web (frontend) | K27: C1 | L27: =IFERROR(IF(K27="","",VLOOKUP(K27,Lists!$K$2:$O$61,5,FALSE)),"") -> The AI assistant can be swapped without disrupting my work | M27: =IFERROR(IF(K27="","",VLOOKUP(K27,Lists!$K$2:$O$61,2,FALSE)),"") -> C | N27: =IFERROR(IF(K27="","",VLOOKUP(K27,Lists!$K$2:$O$61,3,FALSE)),"") -> P1 | O27: - | P27: Scrum-6 completed, implement Custom task & label definition & label list upload & schema driven AI output & label editing in project policy page | Q27: No - more work to come
A28: 46286 | B28: =IF(A28="","",IFERROR(LOOKUP(A28,Lists!$U$2:$U$14,Lists!$T$2:$T$14),"")) -> W7 | C28: Tim Chung | E28: =IF(OR(C28="",D28=""),"",IF(C28=D28,"SELF-REVIEW","OK")) | F28: SCRUM-20 | G28: 28 | H28: https://github.com/USYD-CS-Capstone/hej/pull/28 | L28: =IFERROR(IF(K28="","",VLOOKUP(K28,Lists!$K$2:$O$61,5,FALSE)),"") | M28: =IFERROR(IF(K28="","",VLOOKUP(K28,Lists!$K$2:$O$61,2,FALSE)),"") | N28: =IFERROR(IF(K28="","",VLOOKUP(K28,Lists!$K$2:$O$61,3,FALSE)),"")
A29: 46286 | B29: W8 | C29: Michael Max | E29: =IF(OR(C29="",D29=""),"",IF(C29=D29,"SELF-REVIEW","OK")) | F29: SCRUM-46 | G29: 29 | H29: https://github.com/USYD-CS-Capstone/hej/pull/29 | I29: Feature | L29: =IFERROR(IF(K29="","",VLOOKUP(K29,Lists!$K$2:$O$61,5,FALSE)),"") | M29: =IFERROR(IF(K29="","",VLOOKUP(K29,Lists!$K$2:$O$61,2,FALSE)),"") | N29: =IFERROR(IF(K29="","",VLOOKUP(K29,Lists!$K$2:$O$61,3,FALSE)),"")
A30: 46286 | B30: W8 | C30: Michael Max | E30: =IF(OR(C30="",D30=""),"",IF(C30=D30,"SELF-REVIEW","OK")) | F30: SCRUM-3 | G30: 30 | H30: https://github.com/USYD-CS-Capstone/hej/pull/30 | I30: Feature | L30: =IFERROR(IF(K30="","",VLOOKUP(K30,Lists!$K$2:$O$61,5,FALSE)),"") | M30: =IFERROR(IF(K30="","",VLOOKUP(K30,Lists!$K$2:$O$61,2,FALSE)),"") | N30: =IFERROR(IF(K30="","",VLOOKUP(K30,Lists!$K$2:$O$61,3,FALSE)),"")
A31: 46286 | B31: =IF(A31="","",IFERROR(LOOKUP(A31,Lists!$U$2:$U$14,Lists!$T$2:$T$14),"")) -> W7 | C31: Yi Geng | E31: =IF(OR(C31="",D31=""),"",IF(C31=D31,"SELF-REVIEW","OK")) | L31: =IFERROR(IF(K31="","",VLOOKUP(K31,Lists!$K$2:$O$61,5,FALSE)),"") | M31: =IFERROR(IF(K31="","",VLOOKUP(K31,Lists!$K$2:$O$61,2,FALSE)),"") | N31: =IFERROR(IF(K31="","",VLOOKUP(K31,Lists!$K$2:$O$61,3,FALSE)),"")
B32: =IF(A32="","",IFERROR(LOOKUP(A32,Lists!$U$2:$U$14,Lists!$T$2:$T$14),"")) | E32: =IF(OR(C32="",D32=""),"",IF(C32=D32,"SELF-REVIEW","OK")) | L32: =IFERROR(IF(K32="","",VLOOKUP(K32,Lists!$K$2:$O$61,5,FALSE)),"") | M32: =IFERROR(IF(K32="","",VLOOKUP(K32,Lists!$K$2:$O$61,2,FALSE)),"") | N32: =IFERROR(IF(K32="","",VLOOKUP(K32,Lists!$K$2:$O$61,3,FALSE)),"")
B33: =IF(A33="","",IFERROR(LOOKUP(A33,Lists!$U$2:$U$14,Lists!$T$2:$T$14),"")) | E33: =IF(OR(C33="",D33=""),"",IF(C33=D33,"SELF-REVIEW","OK")) | L33: =IFERROR(IF(K33="","",VLOOKUP(K33,Lists!$K$2:$O$61,5,FALSE)),"") | M33: =IFERROR(IF(K33="","",VLOOKUP(K33,Lists!$K$2:$O$61,2,FALSE)),"") | N33: =IFERROR(IF(K33="","",VLOOKUP(K33,Lists!$K$2:$O$61,3,FALSE)),"")
B34: =IF(A34="","",IFERROR(LOOKUP(A34,Lists!$U$2:$U$14,Lists!$T$2:$T$14),"")) | E34: =IF(OR(C34="",D34=""),"",IF(C34=D34,"SELF-REVIEW","OK")) | L34: =IFERROR(IF(K34="","",VLOOKUP(K34,Lists!$K$2:$O$61,5,FALSE)),"") | M34: =IFERROR(IF(K34="","",VLOOKUP(K34,Lists!$K$2:$O$61,2,FALSE)),"") | N34: =IFERROR(IF(K34="","",VLOOKUP(K34,Lists!$K$2:$O$61,3,FALSE)),"")
B35: =IF(A35="","",IFERROR(LOOKUP(A35,Lists!$U$2:$U$14,Lists!$T$2:$T$14),"")) | E35: =IF(OR(C35="",D35=""),"",IF(C35=D35,"SELF-REVIEW","OK")) | L35: =IFERROR(IF(K35="","",VLOOKUP(K35,Lists!$K$2:$O$61,5,FALSE)),"") | M35: =IFERROR(IF(K35="","",VLOOKUP(K35,Lists!$K$2:$O$61,2,FALSE)),"") | N35: =IFERROR(IF(K35="","",VLOOKUP(K35,Lists!$K$2:$O$61,3,FALSE)),"")
B36: =IF(A36="","",IFERROR(LOOKUP(A36,Lists!$U$2:$U$14,Lists!$T$2:$T$14),"")) | E36: =IF(OR(C36="",D36=""),"",IF(C36=D36,"SELF-REVIEW","OK")) | L36: =IFERROR(IF(K36="","",VLOOKUP(K36,Lists!$K$2:$O$61,5,FALSE)),"") | M36: =IFERROR(IF(K36="","",VLOOKUP(K36,Lists!$K$2:$O$61,2,FALSE)),"") | N36: =IFERROR(IF(K36="","",VLOOKUP(K36,Lists!$K$2:$O$61,3,FALSE)),"")
B37: =IF(A37="","",IFERROR(LOOKUP(A37,Lists!$U$2:$U$14,Lists!$T$2:$T$14),"")) | E37: =IF(OR(C37="",D37=""),"",IF(C37=D37,"SELF-REVIEW","OK")) | L37: =IFERROR(IF(K37="","",VLOOKUP(K37,Lists!$K$2:$O$61,5,FALSE)),"") | M37: =IFERROR(IF(K37="","",VLOOKUP(K37,Lists!$K$2:$O$61,2,FALSE)),"") | N37: =IFERROR(IF(K37="","",VLOOKUP(K37,Lists!$K$2:$O$61,3,FALSE)),"")
B38: =IF(A38="","",IFERROR(LOOKUP(A38,Lists!$U$2:$U$14,Lists!$T$2:$T$14),"")) | E38: =IF(OR(C38="",D38=""),"",IF(C38=D38,"SELF-REVIEW","OK")) | L38: =IFERROR(IF(K38="","",VLOOKUP(K38,Lists!$K$2:$O$61,5,FALSE)),"") | M38: =IFERROR(IF(K38="","",VLOOKUP(K38,Lists!$K$2:$O$61,2,FALSE)),"") | N38: =IFERROR(IF(K38="","",VLOOKUP(K38,Lists!$K$2:$O$61,3,FALSE)),"")
B39: =IF(A39="","",IFERROR(LOOKUP(A39,Lists!$U$2:$U$14,Lists!$T$2:$T$14),"")) | E39: =IF(OR(C39="",D39=""),"",IF(C39=D39,"SELF-REVIEW","OK")) | L39: =IFERROR(IF(K39="","",VLOOKUP(K39,Lists!$K$2:$O$61,5,FALSE)),"") | M39: =IFERROR(IF(K39="","",VLOOKUP(K39,Lists!$K$2:$O$61,2,FALSE)),"") | N39: =IFERROR(IF(K39="","",VLOOKUP(K39,Lists!$K$2:$O$61,3,FALSE)),"")
B40: =IF(A40="","",IFERROR(LOOKUP(A40,Lists!$U$2:$U$14,Lists!$T$2:$T$14),"")) | E40: =IF(OR(C40="",D40=""),"",IF(C40=D40,"SELF-REVIEW","OK")) | L40: =IFERROR(IF(K40="","",VLOOKUP(K40,Lists!$K$2:$O$61,5,FALSE)),"") | M40: =IFERROR(IF(K40="","",VLOOKUP(K40,Lists!$K$2:$O$61,2,FALSE)),"") | N40: =IFERROR(IF(K40="","",VLOOKUP(K40,Lists!$K$2:$O$61,3,FALSE)),"")
...

Sheet Dashboard
B2: Dashboard
B3: Everything here is calculated from the Contribution Log. Nothing on this tab needs to be typed.
B5: PRS MERGED | E5: STORIES TOUCHED | H5: STORIES COMPLETE | K5: SELF-REVIEWS
B6: =COUNTA('Contribution Log'!$C$2:$C$596) -> 30 | E6: {=SUMPRODUCT((COUNTIF('Contribution Log'!$K$2:$K$596,Lists!$K$3:$K$61)>0)*1)} -> 17 | H6: {=SUMPRODUCT((COUNTIFS('Contribution Log'!$K$2:$K$596,Lists!$K$3:$K$61,'Contribution Log'!$Q$2:$Q$596,"Yes - story complete")>0)*1)} -> 11 | K6: =COUNTIF('Contribution Log'!$E$2:$E$596,"SELF-REVIEW") -> 1
B9: Contribution by member
B10: Member | C10: PRs merged | D10: PRs reviewed | E10: Features | F10: Defect fixes | G10: Tests / docs | H10: Stories completed | I10: First merge | J10: Last merge | K10: Share of PRs
B11: =Lists!$A$2 -> Michael Max | C11: =COUNTIF('Contribution Log'!$C$2:$C$596,Lists!$A$2) -> 9 | D11: =COUNTIF('Contribution Log'!$D$2:$D$596,Lists!$A$2) -> 1 | E11: =COUNTIFS('Contribution Log'!$C$2:$C$596,Lists!$A$2,'Contribution Log'!$I$2:$I$596,"Feature") -> 5 | F11: =COUNTIFS('Contribution Log'!$C$2:$C$596,Lists!$A$2,'Contribution Log'!$I$2:$I$596,"Defect fix") -> 3 | G11: =COUNTIFS('Contribution Log'!$C$2:$C$596,Lists!$A$2,'Contribution Log'!$I$2:$I$596,"Tests")+COUNTIFS('Contribution Log'!$C$2:$C$596,Lists!$A$2,'Contribution Log'!$I$2:$I$596,"Documentation") -> 1 | H11: {=SUMPRODUCT((COUNTIFS('Contribution Log'!$K$2:$K$596,Lists!$K$3:$K$61,'Contribution Log'!$C$2:$C$596,Lists!$A$2,'Contribution Log'!$Q$2:$Q$596,"Yes - story complete")>0)*1)} -> 1 | I11: =IF(COUNTIF('Contribution Log'!$C$2:$C$596,Lists!$A$2)=0,"",SUMPRODUCT(MIN(('Contribution Log'!$C$2:$C$596=Lists!$A$2)*'Contribution Log'!$A$2:$A$596+('Contribution Log'!$C$2:$C$596<>Lists!$A$2)*300000))) -> 46277 | J11: =IF(COUNTIF('Contribution Log'!$C$2:$C$596,Lists!$A$2)=0,"",SUMPRODUCT(MAX(('Contribution Log'!$C$2:$C$596=Lists!$A$2)*'Contribution Log'!$A$2:$A$596))) -> 46286 | K11: =IFERROR(COUNTIF('Contribution Log'!$C$2:$C$596,Lists!$A$2)/COUNTA('Contribution Log'!$C$2:$C$596),"") -> 0.3
B12: =Lists!$A$3 -> Parth | C12: =COUNTIF('Contribution Log'!$C$2:$C$596,Lists!$A$3) -> 4 | D12: =COUNTIF('Contribution Log'!$D$2:$D$596,Lists!$A$3) -> 1 | E12: =COUNTIFS('Contribution Log'!$C$2:$C$596,Lists!$A$3,'Contribution Log'!$I$2:$I$596,"Feature") -> 2 | F12: =COUNTIFS('Contribution Log'!$C$2:$C$596,Lists!$A$3,'Contribution Log'!$I$2:$I$596,"Defect fix") -> 1 | G12: =COUNTIFS('Contribution Log'!$C$2:$C$596,Lists!$A$3,'Contribution Log'!$I$2:$I$596,"Tests")+COUNTIFS('Contribution Log'!$C$2:$C$596,Lists!$A$3,'Contribution Log'!$I$2:$I$596,"Documentation") -> 0 | H12: {=SUMPRODUCT((COUNTIFS('Contribution Log'!$K$2:$K$596,Lists!$K$3:$K$61,'Contribution Log'!$C$2:$C$596,Lists!$A$3,'Contribution Log'!$Q$2:$Q$596,"Yes - story complete")>0)*1)} -> 2 | I12: =IF(COUNTIF('Contribution Log'!$C$2:$C$596,Lists!$A$3)=0,"",SUMPRODUCT(MIN(('Contribution Log'!$C$2:$C$596=Lists!$A$3)*'Contribution Log'!$A$2:$A$596+('Contribution Log'!$C$2:$C$596<>Lists!$A$3)*300000))) -> 46279 | J12: =IF(COUNTIF('Contribution Log'!$C$2:$C$596,Lists!$A$3)=0,"",SUMPRODUCT(MAX(('Contribution Log'!$C$2:$C$596=Lists!$A$3)*'Contribution Log'!$A$2:$A$596))) -> 46285 | K12: =IFERROR(COUNTIF('Contribution Log'!$C$2:$C$596,Lists!$A$3)/COUNTA('Contribution Log'!$C$2:$C$596),"") -> 0.13333333
B13: =Lists!$A$4 -> Jingwei Lin | C13: =COUNTIF('Contribution Log'!$C$2:$C$596,Lists!$A$4) -> 4 | D13: =COUNTIF('Contribution Log'!$D$2:$D$596,Lists!$A$4) -> 6 | E13: =COUNTIFS('Contribution Log'!$C$2:$C$596,Lists!$A$4,'Contribution Log'!$I$2:$I$596,"Feature") -> 2 | F13: =COUNTIFS('Contribution Log'!$C$2:$C$596,Lists!$A$4,'Contribution Log'!$I$2:$I$596,"Defect fix") -> 2 | G13: =COUNTIFS('Contribution Log'!$C$2:$C$596,Lists!$A$4,'Contribution Log'!$I$2:$I$596,"Tests")+COUNTIFS('Contribution Log'!$C$2:$C$596,Lists!$A$4,'Contribution Log'!$I$2:$I$596,"Documentation") -> 0 | H13: {=SUMPRODUCT((COUNTIFS('Contribution Log'!$K$2:$K$596,Lists!$K$3:$K$61,'Contribution Log'!$C$2:$C$596,Lists!$A$4,'Contribution Log'!$Q$2:$Q$596,"Yes - story complete")>0)*1)} -> 3 | I13: =IF(COUNTIF('Contribution Log'!$C$2:$C$596,Lists!$A$4)=0,"",SUMPRODUCT(MIN(('Contribution Log'!$C$2:$C$596=Lists!$A$4)*'Contribution Log'!$A$2:$A$596+('Contribution Log'!$C$2:$C$596<>Lists!$A$4)*300000))) -> 46272 | J13: =IF(COUNTIF('Contribution Log'!$C$2:$C$596,Lists!$A$4)=0,"",SUMPRODUCT(MAX(('Contribution Log'!$C$2:$C$596=Lists!$A$4)*'Contribution Log'!$A$2:$A$596))) -> 46285 | K13: =IFERROR(COUNTIF('Contribution Log'!$C$2:$C$596,Lists!$A$4)/COUNTA('Contribution Log'!$C$2:$C$596),"") -> 0.13333333
B14: =Lists!$A$5 -> Hanchen Wang | C14: =COUNTIF('Contribution Log'!$C$2:$C$596,Lists!$A$5) -> 4 | D14: =COUNTIF('Contribution Log'!$D$2:$D$596,Lists!$A$5) -> 6 | E14: =COUNTIFS('Contribution Log'!$C$2:$C$596,Lists!$A$5,'Contribution Log'!$I$2:$I$596,"Feature") -> 0 | F14: =COUNTIFS('Contribution Log'!$C$2:$C$596,Lists!$A$5,'Contribution Log'!$I$2:$I$596,"Defect fix") -> 3 | G14: =COUNTIFS('Contribution Log'!$C$2:$C$596,Lists!$A$5,'Contribution Log'!$I$2:$I$596,"Tests")+COUNTIFS('Contribution Log'!$C$2:$C$596,Lists!$A$5,'Contribution Log'!$I$2:$I$596,"Documentation") -> 0 | H14: {=SUMPRODUCT((COUNTIFS('Contribution Log'!$K$2:$K$596,Lists!$K$3:$K$61,'Contribution Log'!$C$2:$C$596,Lists!$A$5,'Contribution Log'!$Q$2:$Q$596,"Yes - story complete")>0)*1)} -> 2 | I14: =IF(COUNTIF('Contribution Log'!$C$2:$C$596,Lists!$A$5)=0,"",SUMPRODUCT(MIN(('Contribution Log'!$C$2:$C$596=Lists!$A$5)*'Contribution Log'!$A$2:$A$596+('Contribution Log'!$C$2:$C$596<>Lists!$A$5)*300000))) -> 46272 | J14: =IF(COUNTIF('Contribution Log'!$C$2:$C$596,Lists!$A$5)=0,"",SUMPRODUCT(MAX(('Contribution Log'!$C$2:$C$596=Lists!$A$5)*'Contribution Log'!$A$2:$A$596))) -> 46284 | K14: =IFERROR(COUNTIF('Contribution Log'!$C$2:$C$596,Lists!$A$5)/COUNTA('Contribution Log'!$C$2:$C$596),"") -> 0.13333333
B15: =Lists!$A$6 -> Yi Geng | C15: =COUNTIF('Contribution Log'!$C$2:$C$596,Lists!$A$6) -> 3 | D15: =COUNTIF('Contribution Log'!$D$2:$D$596,Lists!$A$6) -> 6 | E15: =COUNTIFS('Contribution Log'!$C$2:$C$596,Lists!$A$6,'Contribution Log'!$I$2:$I$596,"Feature") -> 1 | F15: =COUNTIFS('Contribution Log'!$C$2:$C$596,Lists!$A$6,'Contribution Log'!$I$2:$I$596,"Defect fix") -> 0 | G15: =COUNTIFS('Contribution Log'!$C$2:$C$596,Lists!$A$6,'Contribution Log'!$I$2:$I$596,"Tests")+COUNTIFS('Contribution Log'!$C$2:$C$596,Lists!$A$6,'Contribution Log'!$I$2:$I$596,"Documentation") -> 0 | H15: {=SUMPRODUCT((COUNTIFS('Contribution Log'!$K$2:$K$596,Lists!$K$3:$K$61,'Contribution Log'!$C$2:$C$596,Lists!$A$6,'Contribution Log'!$Q$2:$Q$596,"Yes - story complete")>0)*1)} -> 0 | I15: =IF(COUNTIF('Contribution Log'!$C$2:$C$596,Lists!$A$6)=0,"",SUMPRODUCT(MIN(('Contribution Log'!$C$2:$C$596=Lists!$A$6)*'Contribution Log'!$A$2:$A$596+('Contribution Log'!$C$2:$C$596<>Lists!$A$6)*300000))) -> 46262 | J15: =IF(COUNTIF('Contribution Log'!$C$2:$C$596,Lists!$A$6)=0,"",SUMPRODUCT(MAX(('Contribution Log'!$C$2:$C$596=Lists!$A$6)*'Contribution Log'!$A$2:$A$596))) -> 46286 | K15: =IFERROR(COUNTIF('Contribution Log'!$C$2:$C$596,Lists!$A$6)/COUNTA('Contribution Log'!$C$2:$C$596),"") -> 0.1
B16: =Lists!$A$7 -> Dishank Aswal | C16: =COUNTIF('Contribution Log'!$C$2:$C$596,Lists!$A$7) -> 3 | D16: =COUNTIF('Contribution Log'!$D$2:$D$596,Lists!$A$7) -> 4 | E16: =COUNTIFS('Contribution Log'!$C$2:$C$596,Lists!$A$7,'Contribution Log'!$I$2:$I$596,"Feature") -> 0 | F16: =COUNTIFS('Contribution Log'!$C$2:$C$596,Lists!$A$7,'Contribution Log'!$I$2:$I$596,"Defect fix") -> 2 | G16: =COUNTIFS('Contribution Log'!$C$2:$C$596,Lists!$A$7,'Contribution Log'!$I$2:$I$596,"Tests")+COUNTIFS('Contribution Log'!$C$2:$C$596,Lists!$A$7,'Contribution Log'!$I$2:$I$596,"Documentation") -> 0 | H16: {=SUMPRODUCT((COUNTIFS('Contribution Log'!$K$2:$K$596,Lists!$K$3:$K$61,'Contribution Log'!$C$2:$C$596,Lists!$A$7,'Contribution Log'!$Q$2:$Q$596,"Yes - story complete")>0)*1)} -> 3 | I16: =IF(COUNTIF('Contribution Log'!$C$2:$C$596,Lists!$A$7)=0,"",SUMPRODUCT(MIN(('Contribution Log'!$C$2:$C$596=Lists!$A$7)*'Contribution Log'!$A$2:$A$596+('Contribution Log'!$C$2:$C$596<>Lists!$A$7)*300000))) -> 46277 | J16: =IF(COUNTIF('Contribution Log'!$C$2:$C$596,Lists!$A$7)=0,"",SUMPRODUCT(MAX(('Contribution Log'!$C$2:$C$596=Lists!$A$7)*'Contribution Log'!$A$2:$A$596))) -> 46285 | K16: =IFERROR(COUNTIF('Contribution Log'!$C$2:$C$596,Lists!$A$7)/COUNTA('Contribution Log'!$C$2:$C$596),"") -> 0.1
B17: =Lists!$A$8 -> Kanishka Kathait | C17: =COUNTIF('Contribution Log'!$C$2:$C$596,Lists!$A$8) -> 1 | D17: =COUNTIF('Contribution Log'!$D$2:$D$596,Lists!$A$8) -> 2 | E17: =COUNTIFS('Contribution Log'!$C$2:$C$596,Lists!$A$8,'Contribution Log'!$I$2:$I$596,"Feature") -> 0 | F17: =COUNTIFS('Contribution Log'!$C$2:$C$596,Lists!$A$8,'Contribution Log'!$I$2:$I$596,"Defect fix") -> 1 | G17: =COUNTIFS('Contribution Log'!$C$2:$C$596,Lists!$A$8,'Contribution Log'!$I$2:$I$596,"Tests")+COUNTIFS('Contribution Log'!$C$2:$C$596,Lists!$A$8,'Contribution Log'!$I$2:$I$596,"Documentation") -> 0 | H17: {=SUMPRODUCT((COUNTIFS('Contribution Log'!$K$2:$K$596,Lists!$K$3:$K$61,'Contribution Log'!$C$2:$C$596,Lists!$A$8,'Contribution Log'!$Q$2:$Q$596,"Yes - story complete")>0)*1)} -> 0 | I17: =IF(COUNTIF('Contribution Log'!$C$2:$C$596,Lists!$A$8)=0,"",SUMPRODUCT(MIN(('Contribution Log'!$C$2:$C$596=Lists!$A$8)*'Contribution Log'!$A$2:$A$596+('Contribution Log'!$C$2:$C$596<>Lists!$A$8)*300000))) -> 46277 | J17: =IF(COUNTIF('Contribution Log'!$C$2:$C$596,Lists!$A$8)=0,"",SUMPRODUCT(MAX(('Contribution Log'!$C$2:$C$596=Lists!$A$8)*'Contribution Log'!$A$2:$A$596))) -> 46277 | K17: =IFERROR(COUNTIF('Contribution Log'!$C$2:$C$596,Lists!$A$8)/COUNTA('Contribution Log'!$C$2:$C$596),"") -> 0.033333333
B18: =Lists!$A$9 -> Tim Chung | C18: =COUNTIF('Contribution Log'!$C$2:$C$596,Lists!$A$9) -> 2 | D18: =COUNTIF('Contribution Log'!$D$2:$D$596,Lists!$A$9) -> 0 | E18: =COUNTIFS('Contribution Log'!$C$2:$C$596,Lists!$A$9,'Contribution Log'!$I$2:$I$596,"Feature") -> 1 | F18: =COUNTIFS('Contribution Log'!$C$2:$C$596,Lists!$A$9,'Contribution Log'!$I$2:$I$596,"Defect fix") -> 0 | G18: =COUNTIFS('Contribution Log'!$C$2:$C$596,Lists!$A$9,'Contribution Log'!$I$2:$I$596,"Tests")+COUNTIFS('Contribution Log'!$C$2:$C$596,Lists!$A$9,'Contribution Log'!$I$2:$I$596,"Documentation") -> 0 | H18: {=SUMPRODUCT((COUNTIFS('Contribution Log'!$K$2:$K$596,Lists!$K$3:$K$61,'Contribution Log'!$C$2:$C$596,Lists!$A$9,'Contribution Log'!$Q$2:$Q$596,"Yes - story complete")>0)*1)} -> 0 | I18: =IF(COUNTIF('Contribution Log'!$C$2:$C$596,Lists!$A$9)=0,"",SUMPRODUCT(MIN(('Contribution Log'!$C$2:$C$596=Lists!$A$9)*'Contribution Log'!$A$2:$A$596+('Contribution Log'!$C$2:$C$596<>Lists!$A$9)*300000))) -> 46279 | J18: =IF(COUNTIF('Contribution Log'!$C$2:$C$596,Lists!$A$9)=0,"",SUMPRODUCT(MAX(('Contribution Log'!$C$2:$C$596=Lists!$A$9)*'Contribution Log'!$A$2:$A$596))) -> 46286 | K18: =IFERROR(COUNTIF('Contribution Log'!$C$2:$C$596,Lists!$A$9)/COUNTA('Contribution Log'!$C$2:$C$596),"") -> 0.066666667
B19: TOTAL | C19: =SUM(C11:C18) -> 30 | D19: =SUM(D11:D18) -> 26 | E19: =SUM(E11:E18) -> 11 | F19: =SUM(F11:F18) -> 12 | G19: =SUM(G11:G18) -> 1 | H19: {=SUMPRODUCT((COUNTIFS('Contribution Log'!$K$2:$K$596,Lists!$K$3:$K$61,'Contribution Log'!$Q$2:$Q$596,"Yes - story complete")>0)*1)} -> 11
B20: TOTAL counts distinct stories, so it can be lower than the column above if two people finished the same story.
B22: PRs merged per week | H22: Weeks are calculated from the date merged. Blank weeks simply have nothing logged yet.
B23: Week | C23: =Lists!$A$2 -> Michael Max | D23: =Lists!$A$3 -> Parth | E23: =Lists!$A$4 -> Jingwei Lin | F23: =Lists!$A$5 -> Hanchen Wang | G23: =Lists!$A$6 -> Yi Geng | H23: =Lists!$A$7 -> Dishank Aswal | I23: =Lists!$A$8 -> Kanishka Kathait | J23: =Lists!$A$9 -> Tim Chung | K23: Total
B24: W1 | C24: =COUNTIFS('Contribution Log'!$B$2:$B$596,"W1",'Contribution Log'!$C$2:$C$596,Lists!$A$2) -> 0 | D24: =COUNTIFS('Contribution Log'!$B$2:$B$596,"W1",'Contribution Log'!$C$2:$C$596,Lists!$A$3) -> 0 | E24: =COUNTIFS('Contribution Log'!$B$2:$B$596,"W1",'Contribution Log'!$C$2:$C$596,Lists!$A$4) -> 0 | F24: =COUNTIFS('Contribution Log'!$B$2:$B$596,"W1",'Contribution Log'!$C$2:$C$596,Lists!$A$5) -> 0 | G24: =COUNTIFS('Contribution Log'!$B$2:$B$596,"W1",'Contribution Log'!$C$2:$C$596,Lists!$A$6) -> 0 | H24: =COUNTIFS('Contribution Log'!$B$2:$B$596,"W1",'Contribution Log'!$C$2:$C$596,Lists!$A$7) -> 0 | I24: =COUNTIFS('Contribution Log'!$B$2:$B$596,"W1",'Contribution Log'!$C$2:$C$596,Lists!$A$8) -> 0 | J24: =COUNTIFS('Contribution Log'!$B$2:$B$596,"W1",'Contribution Log'!$C$2:$C$596,Lists!$A$9) -> 0 | K24: =COUNTIF('Contribution Log'!$B$2:$B$596,"W1") -> 0
B25: W2 | C25: =COUNTIFS('Contribution Log'!$B$2:$B$596,"W2",'Contribution Log'!$C$2:$C$596,Lists!$A$2) -> 0 | D25: =COUNTIFS('Contribution Log'!$B$2:$B$596,"W2",'Contribution Log'!$C$2:$C$596,Lists!$A$3) -> 0 | E25: =COUNTIFS('Contribution Log'!$B$2:$B$596,"W2",'Contribution Log'!$C$2:$C$596,Lists!$A$4) -> 0 | F25: =COUNTIFS('Contribution Log'!$B$2:$B$596,"W2",'Contribution Log'!$C$2:$C$596,Lists!$A$5) -> 0 | G25: =COUNTIFS('Contribution Log'!$B$2:$B$596,"W2",'Contribution Log'!$C$2:$C$596,Lists!$A$6) -> 0 | H25: =COUNTIFS('Contribution Log'!$B$2:$B$596,"W2",'Contribution Log'!$C$2:$C$596,Lists!$A$7) -> 0 | I25: =COUNTIFS('Contribution Log'!$B$2:$B$596,"W2",'Contribution Log'!$C$2:$C$596,Lists!$A$8) -> 0 | J25: =COUNTIFS('Contribution Log'!$B$2:$B$596,"W2",'Contribution Log'!$C$2:$C$596,Lists!$A$9) -> 0 | K25: =COUNTIF('Contribution Log'!$B$2:$B$596,"W2") -> 0
B26: W3 | C26: =COUNTIFS('Contribution Log'!$B$2:$B$596,"W3",'Contribution Log'!$C$2:$C$596,Lists!$A$2) -> 0 | D26: =COUNTIFS('Contribution Log'!$B$2:$B$596,"W3",'Contribution Log'!$C$2:$C$596,Lists!$A$3) -> 0 | E26: =COUNTIFS('Contribution Log'!$B$2:$B$596,"W3",'Contribution Log'!$C$2:$C$596,Lists!$A$4) -> 0 | F26: =COUNTIFS('Contribution Log'!$B$2:$B$596,"W3",'Contribution Log'!$C$2:$C$596,Lists!$A$5) -> 0 | G26: =COUNTIFS('Contribution Log'!$B$2:$B$596,"W3",'Contribution Log'!$C$2:$C$596,Lists!$A$6) -> 0 | H26: =COUNTIFS('Contribution Log'!$B$2:$B$596,"W3",'Contribution Log'!$C$2:$C$596,Lists!$A$7) -> 0 | I26: =COUNTIFS('Contribution Log'!$B$2:$B$596,"W3",'Contribution Log'!$C$2:$C$596,Lists!$A$8) -> 0 | J26: =COUNTIFS('Contribution Log'!$B$2:$B$596,"W3",'Contribution Log'!$C$2:$C$596,Lists!$A$9) -> 0 | K26: =COUNTIF('Contribution Log'!$B$2:$B$596,"W3") -> 0
B27: W4 | C27: =COUNTIFS('Contribution Log'!$B$2:$B$596,"W4",'Contribution Log'!$C$2:$C$596,Lists!$A$2) -> 0 | D27: =COUNTIFS('Contribution Log'!$B$2:$B$596,"W4",'Contribution Log'!$C$2:$C$596,Lists!$A$3) -> 0 | E27: =COUNTIFS('Contribution Log'!$B$2:$B$596,"W4",'Contribution Log'!$C$2:$C$596,Lists!$A$4) -> 0 | F27: =COUNTIFS('Contribution Log'!$B$2:$B$596,"W4",'Contribution Log'!$C$2:$C$596,Lists!$A$5) -> 0 | G27: =COUNTIFS('Contribution Log'!$B$2:$B$596,"W4",'Contribution Log'!$C$2:$C$596,Lists!$A$6) -> 1 | H27: =COUNTIFS('Contribution Log'!$B$2:$B$596,"W4",'Contribution Log'!$C$2:$C$596,Lists!$A$7) -> 0 | I27: =COUNTIFS('Contribution Log'!$B$2:$B$596,"W4",'Contribution Log'!$C$2:$C$596,Lists!$A$8) -> 0 | J27: =COUNTIFS('Contribution Log'!$B$2:$B$596,"W4",'Contribution Log'!$C$2:$C$596,Lists!$A$9) -> 0 | K27: =COUNTIF('Contribution Log'!$B$2:$B$596,"W4") -> 1
B28: W5 | C28: =COUNTIFS('Contribution Log'!$B$2:$B$596,"W5",'Contribution Log'!$C$2:$C$596,Lists!$A$2) -> 0 | D28: =COUNTIFS('Contribution Log'!$B$2:$B$596,"W5",'Contribution Log'!$C$2:$C$596,Lists!$A$3) -> 0 | E28: =COUNTIFS('Contribution Log'!$B$2:$B$596,"W5",'Contribution Log'!$C$2:$C$596,Lists!$A$4) -> 0 | F28: =COUNTIFS('Contribution Log'!$B$2:$B$596,"W5",'Contribution Log'!$C$2:$C$596,Lists!$A$5) -> 0 | G28: =COUNTIFS('Contribution Log'!$B$2:$B$596,"W5",'Contribution Log'!$C$2:$C$596,Lists!$A$6) -> 0 | H28: =COUNTIFS('Contribution Log'!$B$2:$B$596,"W5",'Contribution Log'!$C$2:$C$596,Lists!$A$7) -> 0 | I28: =COUNTIFS('Contribution Log'!$B$2:$B$596,"W5",'Contribution Log'!$C$2:$C$596,Lists!$A$8) -> 0 | J28: =COUNTIFS('Contribution Log'!$B$2:$B$596,"W5",'Contribution Log'!$C$2:$C$596,Lists!$A$9) -> 0 | K28: =COUNTIF('Contribution Log'!$B$2:$B$596,"W5") -> 0
B29: W6 | C29: =COUNTIFS('Contribution Log'!$B$2:$B$596,"W6",'Contribution Log'!$C$2:$C$596,Lists!$A$2) -> 3 | D29: =COUNTIFS('Contribution Log'!$B$2:$B$596,"W6",'Contribution Log'!$C$2:$C$596,Lists!$A$3) -> 0 | E29: =COUNTIFS('Contribution Log'!$B$2:$B$596,"W6",'Contribution Log'!$C$2:$C$596,Lists!$A$4) -> 3 | F29: =COUNTIFS('Contribution Log'!$B$2:$B$596,"W6",'Contribution Log'!$C$2:$C$596,Lists!$A$5) -> 2 | G29: =COUNTIFS('Contribution Log'!$B$2:$B$596,"W6",'Contribution Log'!$C$2:$C$596,Lists!$A$6) -> 0 | H29: =COUNTIFS('Contribution Log'!$B$2:$B$596,"W6",'Contribution Log'!$C$2:$C$596,Lists!$A$7) -> 2 | I29: =COUNTIFS('Contribution Log'!$B$2:$B$596,"W6",'Contribution Log'!$C$2:$C$596,Lists!$A$8) -> 1 | J29: =COUNTIFS('Contribution Log'!$B$2:$B$596,"W6",'Contribution Log'!$C$2:$C$596,Lists!$A$9) -> 0 | K29: =COUNTIF('Contribution Log'!$B$2:$B$596,"W6") -> 11
B30: W7 | C30: =COUNTIFS('Contribution Log'!$B$2:$B$596,"W7",'Contribution Log'!$C$2:$C$596,Lists!$A$2) -> 4 | D30: =COUNTIFS('Contribution Log'!$B$2:$B$596,"W7",'Contribution Log'!$C$2:$C$596,Lists!$A$3) -> 4 | E30: =COUNTIFS('Contribution Log'!$B$2:$B$596,"W7",'Contribution Log'!$C$2:$C$596,Lists!$A$4) -> 1 | F30: =COUNTIFS('Contribution Log'!$B$2:$B$596,"W7",'Contribution Log'!$C$2:$C$596,Lists!$A$5) -> 2 | G30: =COUNTIFS('Contribution Log'!$B$2:$B$596,"W7",'Contribution Log'!$C$2:$C$596,Lists!$A$6) -> 2 | H30: =COUNTIFS('Contribution Log'!$B$2:$B$596,"W7",'Contribution Log'!$C$2:$C$596,Lists!$A$7) -> 1 | I30: =COUNTIFS('Contribution Log'!$B$2:$B$596,"W7",'Contribution Log'!$C$2:$C$596,Lists!$A$8) -> 0 | J30: =COUNTIFS('Contribution Log'!$B$2:$B$596,"W7",'Contribution Log'!$C$2:$C$596,Lists!$A$9) -> 2 | K30: =COUNTIF('Contribution Log'!$B$2:$B$596,"W7") -> 16
B31: W8 | C31: =COUNTIFS('Contribution Log'!$B$2:$B$596,"W8",'Contribution Log'!$C$2:$C$596,Lists!$A$2) -> 2 | D31: =COUNTIFS('Contribution Log'!$B$2:$B$596,"W8",'Contribution Log'!$C$2:$C$596,Lists!$A$3) -> 0 | E31: =COUNTIFS('Contribution Log'!$B$2:$B$596,"W8",'Contribution Log'!$C$2:$C$596,Lists!$A$4) -> 0 | F31: =COUNTIFS('Contribution Log'!$B$2:$B$596,"W8",'Contribution Log'!$C$2:$C$596,Lists!$A$5) -> 0 | G31: =COUNTIFS('Contribution Log'!$B$2:$B$596,"W8",'Contribution Log'!$C$2:$C$596,Lists!$A$6) -> 0 | H31: =COUNTIFS('Contribution Log'!$B$2:$B$596,"W8",'Contribution Log'!$C$2:$C$596,Lists!$A$7) -> 0 | I31: =COUNTIFS('Contribution Log'!$B$2:$B$596,"W8",'Contribution Log'!$C$2:$C$596,Lists!$A$8) -> 0 | J31: =COUNTIFS('Contribution Log'!$B$2:$B$596,"W8",'Contribution Log'!$C$2:$C$596,Lists!$A$9) -> 0 | K31: =COUNTIF('Contribution Log'!$B$2:$B$596,"W8") -> 2
B32: Break | C32: =COUNTIFS('Contribution Log'!$B$2:$B$596,"Break",'Contribution Log'!$C$2:$C$596,Lists!$A$2) -> 0 | D32: =COUNTIFS('Contribution Log'!$B$2:$B$596,"Break",'Contribution Log'!$C$2:$C$596,Lists!$A$3) -> 0 | E32: =COUNTIFS('Contribution Log'!$B$2:$B$596,"Break",'Contribution Log'!$C$2:$C$596,Lists!$A$4) -> 0 | F32: =COUNTIFS('Contribution Log'!$B$2:$B$596,"Break",'Contribution Log'!$C$2:$C$596,Lists!$A$5) -> 0 | G32: =COUNTIFS('Contribution Log'!$B$2:$B$596,"Break",'Contribution Log'!$C$2:$C$596,Lists!$A$6) -> 0 | H32: =COUNTIFS('Contribution Log'!$B$2:$B$596,"Break",'Contribution Log'!$C$2:$C$596,Lists!$A$7) -> 0 | I32: =COUNTIFS('Contribution Log'!$B$2:$B$596,"Break",'Contribution Log'!$C$2:$C$596,Lists!$A$8) -> 0 | J32: =COUNTIFS('Contribution Log'!$B$2:$B$596,"Break",'Contribution Log'!$C$2:$C$596,Lists!$A$9) -> 0 | K32: =COUNTIF('Contribution Log'!$B$2:$B$596,"Break") -> 0
B33: W9 | C33: =COUNTIFS('Contribution Log'!$B$2:$B$596,"W9",'Contribution Log'!$C$2:$C$596,Lists!$A$2) -> 0 | D33: =COUNTIFS('Contribution Log'!$B$2:$B$596,"W9",'Contribution Log'!$C$2:$C$596,Lists!$A$3) -> 0 | E33: =COUNTIFS('Contribution Log'!$B$2:$B$596,"W9",'Contribution Log'!$C$2:$C$596,Lists!$A$4) -> 0 | F33: =COUNTIFS('Contribution Log'!$B$2:$B$596,"W9",'Contribution Log'!$C$2:$C$596,Lists!$A$5) -> 0 | G33: =COUNTIFS('Contribution Log'!$B$2:$B$596,"W9",'Contribution Log'!$C$2:$C$596,Lists!$A$6) -> 0 | H33: =COUNTIFS('Contribution Log'!$B$2:$B$596,"W9",'Contribution Log'!$C$2:$C$596,Lists!$A$7) -> 0 | I33: =COUNTIFS('Contribution Log'!$B$2:$B$596,"W9",'Contribution Log'!$C$2:$C$596,Lists!$A$8) -> 0 | J33: =COUNTIFS('Contribution Log'!$B$2:$B$596,"W9",'Contribution Log'!$C$2:$C$596,Lists!$A$9) -> 0 | K33: =COUNTIF('Contribution Log'!$B$2:$B$596,"W9") -> 0
B34: W10 | C34: =COUNTIFS('Contribution Log'!$B$2:$B$596,"W10",'Contribution Log'!$C$2:$C$596,Lists!$A$2) -> 0 | D34: =COUNTIFS('Contribution Log'!$B$2:$B$596,"W10",'Contribution Log'!$C$2:$C$596,Lists!$A$3) -> 0 | E34: =COUNTIFS('Contribution Log'!$B$2:$B$596,"W10",'Contribution Log'!$C$2:$C$596,Lists!$A$4) -> 0 | F34: =COUNTIFS('Contribution Log'!$B$2:$B$596,"W10",'Contribution Log'!$C$2:$C$596,Lists!$A$5) -> 0 | G34: =COUNTIFS('Contribution Log'!$B$2:$B$596,"W10",'Contribution Log'!$C$2:$C$596,Lists!$A$6) -> 0 | H34: =COUNTIFS('Contribution Log'!$B$2:$B$596,"W10",'Contribution Log'!$C$2:$C$596,Lists!$A$7) -> 0 | I34: =COUNTIFS('Contribution Log'!$B$2:$B$596,"W10",'Contribution Log'!$C$2:$C$596,Lists!$A$8) -> 0 | J34: =COUNTIFS('Contribution Log'!$B$2:$B$596,"W10",'Contribution Log'!$C$2:$C$596,Lists!$A$9) -> 0 | K34: =COUNTIF('Contribution Log'!$B$2:$B$596,"W10") -> 0
B35: W11 | C35: =COUNTIFS('Contribution Log'!$B$2:$B$596,"W11",'Contribution Log'!$C$2:$C$596,Lists!$A$2) -> 0 | D35: =COUNTIFS('Contribution Log'!$B$2:$B$596,"W11",'Contribution Log'!$C$2:$C$596,Lists!$A$3) -> 0 | E35: =COUNTIFS('Contribution Log'!$B$2:$B$596,"W11",'Contribution Log'!$C$2:$C$596,Lists!$A$4) -> 0 | F35: =COUNTIFS('Contribution Log'!$B$2:$B$596,"W11",'Contribution Log'!$C$2:$C$596,Lists!$A$5) -> 0 | G35: =COUNTIFS('Contribution Log'!$B$2:$B$596,"W11",'Contribution Log'!$C$2:$C$596,Lists!$A$6) -> 0 | H35: =COUNTIFS('Contribution Log'!$B$2:$B$596,"W11",'Contribution Log'!$C$2:$C$596,Lists!$A$7) -> 0 | I35: =COUNTIFS('Contribution Log'!$B$2:$B$596,"W11",'Contribution Log'!$C$2:$C$596,Lists!$A$8) -> 0 | J35: =COUNTIFS('Contribution Log'!$B$2:$B$596,"W11",'Contribution Log'!$C$2:$C$596,Lists!$A$9) -> 0 | K35: =COUNTIF('Contribution Log'!$B$2:$B$596,"W11") -> 0
B36: W12 | C36: =COUNTIFS('Contribution Log'!$B$2:$B$596,"W12",'Contribution Log'!$C$2:$C$596,Lists!$A$2) -> 0 | D36: =COUNTIFS('Contribution Log'!$B$2:$B$596,"W12",'Contribution Log'!$C$2:$C$596,Lists!$A$3) -> 0 | E36: =COUNTIFS('Contribution Log'!$B$2:$B$596,"W12",'Contribution Log'!$C$2:$C$596,Lists!$A$4) -> 0 | F36: =COUNTIFS('Contribution Log'!$B$2:$B$596,"W12",'Contribution Log'!$C$2:$C$596,Lists!$A$5) -> 0 | G36: =COUNTIFS('Contribution Log'!$B$2:$B$596,"W12",'Contribution Log'!$C$2:$C$596,Lists!$A$6) -> 0 | H36: =COUNTIFS('Contribution Log'!$B$2:$B$596,"W12",'Contribution Log'!$C$2:$C$596,Lists!$A$7) -> 0 | I36: =COUNTIFS('Contribution Log'!$B$2:$B$596,"W12",'Contribution Log'!$C$2:$C$596,Lists!$A$8) -> 0 | J36: =COUNTIFS('Contribution Log'!$B$2:$B$596,"W12",'Contribution Log'!$C$2:$C$596,Lists!$A$9) -> 0 | K36: =COUNTIF('Contribution Log'!$B$2:$B$596,"W12") -> 0
B38: Where the work went | H38: Review health
B39: Area / repo | C39: PRs | E39: Work type | F39: PRs
B40: =Lists!$E$2 -> hej-web (frontend) | C40: =COUNTIF('Contribution Log'!$J$2:$J$596,Lists!$E$2) -> 5 | E40: =Lists!$D$2 -> Feature | F40: =COUNTIF('Contribution Log'!$I$2:$I$596,Lists!$D$2) -> 11 | H40: PRs with a named reviewer | I40: =COUNTIF('Contribution Log'!$E$2:$E$596,"OK") -> 25
B41: =Lists!$E$3 -> hej-api (backend) | C41: =COUNTIF('Contribution Log'!$J$2:$J$596,Lists!$E$3) -> 14 | E41: =Lists!$D$3 -> Defect fix | F41: =COUNTIF('Contribution Log'!$I$2:$I$596,Lists!$D$3) -> 12 | H41: PRs reviewed by their own author | I41: =COUNTIF('Contribution Log'!$E$2:$E$596,"SELF-REVIEW") -> 1
B42: =Lists!$E$4 -> packages/ui | C42: =COUNTIF('Contribution Log'!$J$2:$J$596,Lists!$E$4) -> 0 | E42: =Lists!$D$4 -> Refactor | F42: =COUNTIF('Contribution Log'!$I$2:$I$596,Lists!$D$4) -> 2 | H42: Rows with no reviewer recorded | I42: =SUMPRODUCT(('Contribution Log'!$C$2:$C$596<>"")*('Contribution Log'!$D$2:$D$596="")) -> 4
B43: =Lists!$E$5 -> labeling_ai_assistnat_mvp (AI) | C43: =COUNTIF('Contribution Log'!$J$2:$J$596,Lists!$E$5) -> 1 | E43: =Lists!$D$5 -> Tests | F43: =COUNTIF('Contribution Log'!$I$2:$I$596,Lists!$D$5) -> 0 | H43: Rows with no story linked | I43: =SUMPRODUCT(('Contribution Log'!$C$2:$C$596<>"")*('Contribution Log'!$K$2:$K$596="")) -> 4
B44: =Lists!$E$6 -> Database / schema | C44: =COUNTIF('Contribution Log'!$J$2:$J$596,Lists!$E$6) -> 2 | E44: =Lists!$D$6 -> Documentation | F44: =COUNTIF('Contribution Log'!$I$2:$I$596,Lists!$D$6) -> 1 | H44: Rows missing a plain-English summary | I44: =SUMPRODUCT(('Contribution Log'!$C$2:$C$596<>"")*('Contribution Log'!$P$2:$P$596="")) -> 6
B45: =Lists!$E$7 -> CI / tooling | C45: =COUNTIF('Contribution Log'!$J$2:$J$596,Lists!$E$7) -> 2 | E45: =Lists!$D$7 -> Spike / Research | F45: =COUNTIF('Contribution Log'!$I$2:$I$596,Lists!$D$7) -> 0
B46: =Lists!$E$8 -> Docs / report | C46: =COUNTIF('Contribution Log'!$J$2:$J$596,Lists!$E$8) -> 1 | E46: =Lists!$D$8 -> DevOps / CI | F46: =COUNTIF('Contribution Log'!$I$2:$I$596,Lists!$D$8) -> 2
...

Sheet Jira Statistics
B2: Jira Statistics
B3: The CS-57 board, matched to the 59 committed backlog stories. Status and assignees are a snapshot of docs/Jira.csv; PR counts are live from the Contribution Log. Only the nine Owner cells are typed.
B5: WORK ITEMS | D5: IN PROGRESS | F5: IN REVIEW | H5: DONE | J5: IN SPRINT W7 | L5: UNASSIGNED
B6: 76 | D6: 1 | F6: 3 | H6: 31 | J6: 18 | L6: 36
B8: Work bundles | H8: Fill in the nine Owner cells once. This is the only typing on this tab.
B9: # | C9: Work bundle | D9: What it covers | F9: Stories | G9: To do | H9: Doing | I9: Done | J9: PRs
B10: 1 | C10: AI task queue | D10: Task queue with progress bar; completed / failed / retry | F10: =COUNTIF(Lists!$X$3:$X$61,$C10) -> 1 | G10: =COUNTIFS(Lists!$X$3:$X$61,$C10,Lists!$Y$3:$Y$61,"To Do")+COUNTIFS(Lists!$X$3:$X$61,$C10,Lists!$Y$3:$Y$61,"Not on board") -> 0 | H10: =COUNTIFS(Lists!$X$3:$X$61,$C10,Lists!$Y$3:$Y$61,"In progress") -> 1 | I10: =COUNTIFS(Lists!$X$3:$X$61,$C10,Lists!$Y$3:$Y$61,"Done") -> 0 | J10: {=SUMPRODUCT((Lists!$X$3:$X$61=$C10)*COUNTIF('Contribution Log'!$K$2:$K$596,Lists!$K$3:$K$61))} -> 4
B11: 2 | C11: AI provider & failures | D11: Annotation failure and the fake bounding-box fallback; integrate labeling_ai_assistnat_mvp | F11: =COUNTIF(Lists!$X$3:$X$61,$C11) -> 1 | G11: =COUNTIFS(Lists!$X$3:$X$61,$C11,Lists!$Y$3:$Y$61,"To Do")+COUNTIFS(Lists!$X$3:$X$61,$C11,Lists!$Y$3:$Y$61,"Not on board") -> 0 | H11: =COUNTIFS(Lists!$X$3:$X$61,$C11,Lists!$Y$3:$Y$61,"In progress") -> 0 | I11: =COUNTIFS(Lists!$X$3:$X$61,$C11,Lists!$Y$3:$Y$61,"Done") -> 1 | J11: {=SUMPRODUCT((Lists!$X$3:$X$61=$C11)*COUNTIF('Contribution Log'!$K$2:$K$596,Lists!$K$3:$K$61))} -> 1
B12: 3 | C12: Project setup & status UI | D12: Project / policy / task update, dataset upload, status page | F12: =COUNTIF(Lists!$X$3:$X$61,$C12) -> 7 | G12: =COUNTIFS(Lists!$X$3:$X$61,$C12,Lists!$Y$3:$Y$61,"To Do")+COUNTIFS(Lists!$X$3:$X$61,$C12,Lists!$Y$3:$Y$61,"Not on board") -> 4 | H12: =COUNTIFS(Lists!$X$3:$X$61,$C12,Lists!$Y$3:$Y$61,"In progress") -> 2 | I12: =COUNTIFS(Lists!$X$3:$X$61,$C12,Lists!$Y$3:$Y$61,"Done") -> 1 | J12: {=SUMPRODUCT((Lists!$X$3:$X$61=$C12)*COUNTIF('Contribution Log'!$K$2:$K$596,Lists!$K$3:$K$61))} -> 2
B13: 4 | C13: Task & item backend | D13: Illegal item status, cross-project writes, non-transactional task registration, missing transition out of draft, task-item routes and services | F13: =COUNTIF(Lists!$X$3:$X$61,$C13) -> 4 | G13: =COUNTIFS(Lists!$X$3:$X$61,$C13,Lists!$Y$3:$Y$61,"To Do")+COUNTIFS(Lists!$X$3:$X$61,$C13,Lists!$Y$3:$Y$61,"Not on board") -> 1 | H13: =COUNTIFS(Lists!$X$3:$X$61,$C13,Lists!$Y$3:$Y$61,"In progress") -> 0 | I13: =COUNTIFS(Lists!$X$3:$X$61,$C13,Lists!$Y$3:$Y$61,"Done") -> 3 | J13: {=SUMPRODUCT((Lists!$X$3:$X$61=$C13)*COUNTIF('Contribution Log'!$K$2:$K$596,Lists!$K$3:$K$61))} -> 4
B14: 5 | C14: Annotation page & judgement | D14: Annotation page with judgement feedback or justification | F14: =COUNTIF(Lists!$X$3:$X$61,$C14) -> 6 | G14: =COUNTIFS(Lists!$X$3:$X$61,$C14,Lists!$Y$3:$Y$61,"To Do")+COUNTIFS(Lists!$X$3:$X$61,$C14,Lists!$Y$3:$Y$61,"Not on board") -> 3 | H14: =COUNTIFS(Lists!$X$3:$X$61,$C14,Lists!$Y$3:$Y$61,"In progress") -> 2 | I14: =COUNTIFS(Lists!$X$3:$X$61,$C14,Lists!$Y$3:$Y$61,"Done") -> 1 | J14: {=SUMPRODUCT((Lists!$X$3:$X$61=$C14)*COUNTIF('Contribution Log'!$K$2:$K$596,Lists!$K$3:$K$61))} -> 2
B15: 6 | C15: Draft ownership & verdict | D15: Finalised annotation overwrite, draft ownership, judgement verdict and feedback | F15: =COUNTIF(Lists!$X$3:$X$61,$C15) -> 3 | G15: =COUNTIFS(Lists!$X$3:$X$61,$C15,Lists!$Y$3:$Y$61,"To Do")+COUNTIFS(Lists!$X$3:$X$61,$C15,Lists!$Y$3:$Y$61,"Not on board") -> 1 | H15: =COUNTIFS(Lists!$X$3:$X$61,$C15,Lists!$Y$3:$Y$61,"In progress") -> 0 | I15: =COUNTIFS(Lists!$X$3:$X$61,$C15,Lists!$Y$3:$Y$61,"Done") -> 2 | J15: {=SUMPRODUCT((Lists!$X$3:$X$61=$C15)*COUNTIF('Contribution Log'!$K$2:$K$596,Lists!$K$3:$K$61))} -> 3
B16: 7 | C16: Review, permissions & dispute | D16: Reviewer correction, avoid self-review, review action, permission and dispute | F16: =COUNTIF(Lists!$X$3:$X$61,$C16) -> 8 | G16: =COUNTIFS(Lists!$X$3:$X$61,$C16,Lists!$Y$3:$Y$61,"To Do")+COUNTIFS(Lists!$X$3:$X$61,$C16,Lists!$Y$3:$Y$61,"Not on board") -> 6 | H16: =COUNTIFS(Lists!$X$3:$X$61,$C16,Lists!$Y$3:$Y$61,"In progress") -> 2 | I16: =COUNTIFS(Lists!$X$3:$X$61,$C16,Lists!$Y$3:$Y$61,"Done") -> 0 | J16: {=SUMPRODUCT((Lists!$X$3:$X$61=$C16)*COUNTIF('Contribution Log'!$K$2:$K$596,Lists!$K$3:$K$61))} -> 2
B17: 8 | C17: Audit & history | D17: Audit and history | F17: =COUNTIF(Lists!$X$3:$X$61,$C17) -> 4 | G17: =COUNTIFS(Lists!$X$3:$X$61,$C17,Lists!$Y$3:$Y$61,"To Do")+COUNTIFS(Lists!$X$3:$X$61,$C17,Lists!$Y$3:$Y$61,"Not on board") -> 3 | H17: =COUNTIFS(Lists!$X$3:$X$61,$C17,Lists!$Y$3:$Y$61,"In progress") -> 0 | I17: =COUNTIFS(Lists!$X$3:$X$61,$C17,Lists!$Y$3:$Y$61,"Done") -> 1 | J17: {=SUMPRODUCT((Lists!$X$3:$X$61=$C17)*COUNTIF('Contribution Log'!$K$2:$K$596,Lists!$K$3:$K$61))} -> 1
B18: 9 | C18: Release & export | D18: Release and export | F18: =COUNTIF(Lists!$X$3:$X$61,$C18) -> 5 | G18: =COUNTIFS(Lists!$X$3:$X$61,$C18,Lists!$Y$3:$Y$61,"To Do")+COUNTIFS(Lists!$X$3:$X$61,$C18,Lists!$Y$3:$Y$61,"Not on board") -> 4 | H18: =COUNTIFS(Lists!$X$3:$X$61,$C18,Lists!$Y$3:$Y$61,"In progress") -> 0 | I18: =COUNTIFS(Lists!$X$3:$X$61,$C18,Lists!$Y$3:$Y$61,"Done") -> 1 | J18: {=SUMPRODUCT((Lists!$X$3:$X$61=$C18)*COUNTIF('Contribution Log'!$K$2:$K$596,Lists!$K$3:$K$61))} -> 0
