Workbook

Sheet Start Here
B2: CS-57 - Contribution Tracker
B3: Human-AI Data Annotation, Provenance & Dataset Evaluation Platform | Group CS-57 | Client: Hunter Xu
B5: The one rule
C6: After your pull request is merged into main, add ONE row to the 'Contribution Log' tab. That is the whole process. Every other tab fills itself in from those rows.
B8: What each tab is for
B9: Contribution Log | C9: The only tab you type into. One row per merged PR. Cream headers = you fill in; grey headers = filled in automatically, do not type in them.
B10: Dashboard | C10: Automatic. Who merged what, per week and in total; review health; the split across frontend / backend / AI.
B11: Jira Board | C11: Who owns which bundle, how much of the committed scope is done, workload per person, and every issue on the board matched to the story it serves. Fill in the nine Owner cells once; the rest is a snapshot of docs/Jira.csv plus live PR counts.
B12: Client Report | C12: Set a date range at the top and this becomes the numbers block for the Status Checking form and the weekly client meeting.
B13: Lists | C13: Reference data behind the dropdowns and the automatic columns. Only edit the Week 1 Monday date, and only once.
B15: When you finish a story
C16: Work through this before you ask for a review. If you cannot tick items 1 and 2, the story is not finished - which is fine, but log the PR with 'Story complete? = No'.
C17: 1. Open the story in user-stories.html and re-read its acceptance criteria - every numbered criterion, not the one you remember. This is what 'done' means for that story.
C18: 2. The checks pass: npm run typecheck and the test suite run clean in whatever you touched (story A2).
C19: 3. There is a test covering the behaviour you changed, not only the code you wrote.
C20: 4. Anything a teammate could not guess is written down - a change note, and a decision record if you chose between real alternatives.
C21: 5. Open the PR with the story ID in the title, e.g. 'C2 - task queue progress'.
C22: 6. Request review from someone who did not write the code (story A1), and move the SCRUM ticket to In Review.
C23: 7. Once it is merged: move the SCRUM ticket to Done, then add your row to the Contribution Log.
C24: 8. Set 'Story complete? = Yes' only if every acceptance criterion is now met. If it closed a catalogued defect, put the issue number in 'Defects closed'.
B26: How to log a merged PR
C27: 1. Open 'Contribution Log' and go to the first empty row.
C28: 2. Date merged - the date the PR landed on main. The Week column fills itself in from this.
C29: 3. Member is you. Reviewed by is the teammate who approved the PR. They must be different people (story A1 - no change reaches main without a second person's review); the sheet turns the row red if they are not.
C30: 4. Story ID - pick the backlog story the work serves (A1 ... K4). The story title, epic and priority appear automatically.
C31: 5. What changed - one sentence a non-engineer can understand. This sentence is what gets read out to the client, so write it for the client, not for the team.
C32: 6. Story complete? - answer 'Yes' only when nothing further is needed for that story. This is what drives every progress number in the workbook.
B34: What a good row looks like
C35: Date merged | D35: Member | E35: Reviewed by | F35: Work type | G35: Story ID | H35: What changed (plain English, for the client) | I35: Story complete?
C36: 2026-09-08 | D36: Hanchen Wang | E36: Michael Max | F36: Feature | G36: C2 | H36: A task with 1,000 items now runs in the background and shows a live progress bar, instead of freezing the page. | I36: No - more work to come
C37: 2026-09-09 | D37: Yi Geng | E37: Dishank Aswal | F37: Defect fix | G37: C3 | H37: When the AI is unavailable the item is now marked 'AI failed' instead of being filled with an invented bounding box. | I37: Yes - story complete
C38: 2026-09-10 | D38: Parth | E38: Tok Tin Chung | F38: Client / PM / Report | G38: K2 | H38: Wrote up the Week 6 status report and the client's decision on dispute routing. | I38: N/A - not story work
C39: Note what the summaries do not say: no file names, no function names, no ticket jargon. Write the sentence the client would understand if it were read out loud.
B41: Ground rules
C42: - One row per merged PR - not per commit, and not per day of work.
C43: - Log it the same day it merges. A log reconstructed from memory in Week 12 is worth very little to anyone, including you.
C44: - Never delete or reorder someone else's row. If a row is wrong, correct that row.
C45: - Do not insert, delete or reorder columns. The other tabs read this one by column position and will break.
C46: - Work that is not a PR still counts - client meetings, the report, the proposal, research spikes. Log it with work type 'Client / PM / Report' or 'Spike / Research' and leave the PR number blank.
C47: - If one PR serves two stories, log the row against the main story and name the second one in Notes.
...

Sheet Contribution Log
A1: Date merged | B1: Week | C1: Member | D1: Reviewed by | E1: Review OK? | F1: PR # | G1: PR link | H1: Work type | I1: Area / repo | J1: Story ID | K1: Story title | L1: Epic | M1: Pri | N1: SCRUM ticket | O1: Defects closed | P1: What changed (plain English, for the client) | Q1: Story complete? | R1: Notes / evidence
B2: =IF(A2="","","W"&(INT((A2-Lists!$B$2)/7)+1)) | E2: =IF(OR(C2="",D2=""),"",IF(C2=D2,"SELF-REVIEW","OK")) | K2: =IFERROR(IF(J2="","",VLOOKUP(J2,Lists!$K$2:$O$61,5,FALSE)),"") | L2: =IFERROR(IF(J2="","",VLOOKUP(J2,Lists!$K$2:$O$61,2,FALSE)),"") | M2: =IFERROR(IF(J2="","",VLOOKUP(J2,Lists!$K$2:$O$61,3,FALSE)),"")
B3: =IF(A3="","","W"&(INT((A3-Lists!$B$2)/7)+1)) | E3: =IF(OR(C3="",D3=""),"",IF(C3=D3,"SELF-REVIEW","OK")) | K3: =IFERROR(IF(J3="","",VLOOKUP(J3,Lists!$K$2:$O$61,5,FALSE)),"") | L3: =IFERROR(IF(J3="","",VLOOKUP(J3,Lists!$K$2:$O$61,2,FALSE)),"") | M3: =IFERROR(IF(J3="","",VLOOKUP(J3,Lists!$K$2:$O$61,3,FALSE)),"")
B4: =IF(A4="","","W"&(INT((A4-Lists!$B$2)/7)+1)) | E4: =IF(OR(C4="",D4=""),"",IF(C4=D4,"SELF-REVIEW","OK")) | K4: =IFERROR(IF(J4="","",VLOOKUP(J4,Lists!$K$2:$O$61,5,FALSE)),"") | L4: =IFERROR(IF(J4="","",VLOOKUP(J4,Lists!$K$2:$O$61,2,FALSE)),"") | M4: =IFERROR(IF(J4="","",VLOOKUP(J4,Lists!$K$2:$O$61,3,FALSE)),"")
B5: =IF(A5="","","W"&(INT((A5-Lists!$B$2)/7)+1)) | E5: =IF(OR(C5="",D5=""),"",IF(C5=D5,"SELF-REVIEW","OK")) | K5: =IFERROR(IF(J5="","",VLOOKUP(J5,Lists!$K$2:$O$61,5,FALSE)),"") | L5: =IFERROR(IF(J5="","",VLOOKUP(J5,Lists!$K$2:$O$61,2,FALSE)),"") | M5: =IFERROR(IF(J5="","",VLOOKUP(J5,Lists!$K$2:$O$61,3,FALSE)),"")
B6: =IF(A6="","","W"&(INT((A6-Lists!$B$2)/7)+1)) | E6: =IF(OR(C6="",D6=""),"",IF(C6=D6,"SELF-REVIEW","OK")) | K6: =IFERROR(IF(J6="","",VLOOKUP(J6,Lists!$K$2:$O$61,5,FALSE)),"") | L6: =IFERROR(IF(J6="","",VLOOKUP(J6,Lists!$K$2:$O$61,2,FALSE)),"") | M6: =IFERROR(IF(J6="","",VLOOKUP(J6,Lists!$K$2:$O$61,3,FALSE)),"")
B7: =IF(A7="","","W"&(INT((A7-Lists!$B$2)/7)+1)) | E7: =IF(OR(C7="",D7=""),"",IF(C7=D7,"SELF-REVIEW","OK")) | K7: =IFERROR(IF(J7="","",VLOOKUP(J7,Lists!$K$2:$O$61,5,FALSE)),"") | L7: =IFERROR(IF(J7="","",VLOOKUP(J7,Lists!$K$2:$O$61,2,FALSE)),"") | M7: =IFERROR(IF(J7="","",VLOOKUP(J7,Lists!$K$2:$O$61,3,FALSE)),"")
A8: 46262 | B8: =IF(A8="","","W"&(INT((A8-Lists!$B$2)/7)+1)) -> W4 | C8: Yi Geng | D8: Yi Geng | E8: =IF(OR(C8="",D8=""),"",IF(C8=D8,"SELF-REVIEW","OK")) -> SELF-REVIEW | F8: 1 | H8: Refactor | I8: Other | K8: =IFERROR(IF(J8="","",VLOOKUP(J8,Lists!$K$2:$O$61,5,FALSE)),"") | L8: =IFERROR(IF(J8="","",VLOOKUP(J8,Lists!$K$2:$O$61,2,FALSE)),"") | M8: =IFERROR(IF(J8="","",VLOOKUP(J8,Lists!$K$2:$O$61,3,FALSE)),"") | Q8: No - more work to come
A9: 46272 | B9: =IF(A9="","","W"&(INT((A9-Lists!$B$2)/7)+1)) -> W6 | C9: Hanchen Wang | D9: Jingwei Lin | E9: =IF(OR(C9="",D9=""),"",IF(C9=D9,"SELF-REVIEW","OK")) -> OK | F9: 2 | H9: DevOps / CI | I9: CI / tooling | J9: A2 | K9: =IFERROR(IF(J9="","",VLOOKUP(J9,Lists!$K$2:$O$61,5,FALSE)),"") -> I can trust that a fix in one place hasn't broken another | L9: =IFERROR(IF(J9="","",VLOOKUP(J9,Lists!$K$2:$O$61,2,FALSE)),"") -> A | M9: =IFERROR(IF(J9="","",VLOOKUP(J9,Lists!$K$2:$O$61,3,FALSE)),"") -> P0 | N9: SCRUM-82 | O9: 12,13,25,26 | Q9: Yes - story complete
A10: 46272 | B10: =IF(A10="","","W"&(INT((A10-Lists!$B$2)/7)+1)) -> W6 | C10: Jingwei Lin | D10: Hanchen Wang | E10: =IF(OR(C10="",D10=""),"",IF(C10=D10,"SELF-REVIEW","OK")) -> OK | F10: 4 | H10: Feature | I10: hej-api (backend) | J10: G1 | K10: =IFERROR(IF(J10="","",VLOOKUP(J10,Lists!$K$2:$O$61,5,FALSE)),"") -> My role determines what I can do | L10: =IFERROR(IF(J10="","",VLOOKUP(J10,Lists!$K$2:$O$61,2,FALSE)),"") -> G | M10: =IFERROR(IF(J10="","",VLOOKUP(J10,Lists!$K$2:$O$61,3,FALSE)),"") -> P0 | N10: SCRUM-44 | O10: 7 | P10: Users now can only perform actions that the role allowed them to do. | Q10: Yes - story complete
B11: =IF(A11="","","W"&(INT((A11-Lists!$B$2)/7)+1)) | E11: =IF(OR(C11="",D11=""),"",IF(C11=D11,"SELF-REVIEW","OK")) | K11: =IFERROR(IF(J11="","",VLOOKUP(J11,Lists!$K$2:$O$61,5,FALSE)),"") | L11: =IFERROR(IF(J11="","",VLOOKUP(J11,Lists!$K$2:$O$61,2,FALSE)),"") | M11: =IFERROR(IF(J11="","",VLOOKUP(J11,Lists!$K$2:$O$61,3,FALSE)),"")
B12: =IF(A12="","","W"&(INT((A12-Lists!$B$2)/7)+1)) | E12: =IF(OR(C12="",D12=""),"",IF(C12=D12,"SELF-REVIEW","OK")) | K12: =IFERROR(IF(J12="","",VLOOKUP(J12,Lists!$K$2:$O$61,5,FALSE)),"") | L12: =IFERROR(IF(J12="","",VLOOKUP(J12,Lists!$K$2:$O$61,2,FALSE)),"") | M12: =IFERROR(IF(J12="","",VLOOKUP(J12,Lists!$K$2:$O$61,3,FALSE)),"")
B13: =IF(A13="","","W"&(INT((A13-Lists!$B$2)/7)+1)) | E13: =IF(OR(C13="",D13=""),"",IF(C13=D13,"SELF-REVIEW","OK")) | K13: =IFERROR(IF(J13="","",VLOOKUP(J13,Lists!$K$2:$O$61,5,FALSE)),"") | L13: =IFERROR(IF(J13="","",VLOOKUP(J13,Lists!$K$2:$O$61,2,FALSE)),"") | M13: =IFERROR(IF(J13="","",VLOOKUP(J13,Lists!$K$2:$O$61,3,FALSE)),"")
B14: =IF(A14="","","W"&(INT((A14-Lists!$B$2)/7)+1)) | E14: =IF(OR(C14="",D14=""),"",IF(C14=D14,"SELF-REVIEW","OK")) | K14: =IFERROR(IF(J14="","",VLOOKUP(J14,Lists!$K$2:$O$61,5,FALSE)),"") | L14: =IFERROR(IF(J14="","",VLOOKUP(J14,Lists!$K$2:$O$61,2,FALSE)),"") | M14: =IFERROR(IF(J14="","",VLOOKUP(J14,Lists!$K$2:$O$61,3,FALSE)),"")
B15: =IF(A15="","","W"&(INT((A15-Lists!$B$2)/7)+1)) | E15: =IF(OR(C15="",D15=""),"",IF(C15=D15,"SELF-REVIEW","OK")) | K15: =IFERROR(IF(J15="","",VLOOKUP(J15,Lists!$K$2:$O$61,5,FALSE)),"") | L15: =IFERROR(IF(J15="","",VLOOKUP(J15,Lists!$K$2:$O$61,2,FALSE)),"") | M15: =IFERROR(IF(J15="","",VLOOKUP(J15,Lists!$K$2:$O$61,3,FALSE)),"")
B16: =IF(A16="","","W"&(INT((A16-Lists!$B$2)/7)+1)) | E16: =IF(OR(C16="",D16=""),"",IF(C16=D16,"SELF-REVIEW","OK")) | K16: =IFERROR(IF(J16="","",VLOOKUP(J16,Lists!$K$2:$O$61,5,FALSE)),"") | L16: =IFERROR(IF(J16="","",VLOOKUP(J16,Lists!$K$2:$O$61,2,FALSE)),"") | M16: =IFERROR(IF(J16="","",VLOOKUP(J16,Lists!$K$2:$O$61,3,FALSE)),"")
B17: =IF(A17="","","W"&(INT((A17-Lists!$B$2)/7)+1)) | E17: =IF(OR(C17="",D17=""),"",IF(C17=D17,"SELF-REVIEW","OK")) | K17: =IFERROR(IF(J17="","",VLOOKUP(J17,Lists!$K$2:$O$61,5,FALSE)),"") | L17: =IFERROR(IF(J17="","",VLOOKUP(J17,Lists!$K$2:$O$61,2,FALSE)),"") | M17: =IFERROR(IF(J17="","",VLOOKUP(J17,Lists!$K$2:$O$61,3,FALSE)),"")
B18: =IF(A18="","","W"&(INT((A18-Lists!$B$2)/7)+1)) | E18: =IF(OR(C18="",D18=""),"",IF(C18=D18,"SELF-REVIEW","OK")) | K18: =IFERROR(IF(J18="","",VLOOKUP(J18,Lists!$K$2:$O$61,5,FALSE)),"") | L18: =IFERROR(IF(J18="","",VLOOKUP(J18,Lists!$K$2:$O$61,2,FALSE)),"") | M18: =IFERROR(IF(J18="","",VLOOKUP(J18,Lists!$K$2:$O$61,3,FALSE)),"")
B19: =IF(A19="","","W"&(INT((A19-Lists!$B$2)/7)+1)) | E19: =IF(OR(C19="",D19=""),"",IF(C19=D19,"SELF-REVIEW","OK")) | K19: =IFERROR(IF(J19="","",VLOOKUP(J19,Lists!$K$2:$O$61,5,FALSE)),"") | L19: =IFERROR(IF(J19="","",VLOOKUP(J19,Lists!$K$2:$O$61,2,FALSE)),"") | M19: =IFERROR(IF(J19="","",VLOOKUP(J19,Lists!$K$2:$O$61,3,FALSE)),"")
B20: =IF(A20="","","W"&(INT((A20-Lists!$B$2)/7)+1)) | E20: =IF(OR(C20="",D20=""),"",IF(C20=D20,"SELF-REVIEW","OK")) | K20: =IFERROR(IF(J20="","",VLOOKUP(J20,Lists!$K$2:$O$61,5,FALSE)),"") | L20: =IFERROR(IF(J20="","",VLOOKUP(J20,Lists!$K$2:$O$61,2,FALSE)),"") | M20: =IFERROR(IF(J20="","",VLOOKUP(J20,Lists!$K$2:$O$61,3,FALSE)),"")
B21: =IF(A21="","","W"&(INT((A21-Lists!$B$2)/7)+1)) | E21: =IF(OR(C21="",D21=""),"",IF(C21=D21,"SELF-REVIEW","OK")) | K21: =IFERROR(IF(J21="","",VLOOKUP(J21,Lists!$K$2:$O$61,5,FALSE)),"") | L21: =IFERROR(IF(J21="","",VLOOKUP(J21,Lists!$K$2:$O$61,2,FALSE)),"") | M21: =IFERROR(IF(J21="","",VLOOKUP(J21,Lists!$K$2:$O$61,3,FALSE)),"")
B22: =IF(A22="","","W"&(INT((A22-Lists!$B$2)/7)+1)) | E22: =IF(OR(C22="",D22=""),"",IF(C22=D22,"SELF-REVIEW","OK")) | K22: =IFERROR(IF(J22="","",VLOOKUP(J22,Lists!$K$2:$O$61,5,FALSE)),"") | L22: =IFERROR(IF(J22="","",VLOOKUP(J22,Lists!$K$2:$O$61,2,FALSE)),"") | M22: =IFERROR(IF(J22="","",VLOOKUP(J22,Lists!$K$2:$O$61,3,FALSE)),"")
... B601: =IF(A601="","","W"&(INT((A601-Lists!$B$2)/7)+1)) | E601: =IF(OR(C601="",D601=""),"",IF(C601=D601,"SELF-REVIEW","OK")) | K601: =IFERROR(IF(J601="","",VLOOKUP(J601,Lists!$K$2:$O$61,5,FALSE)),"") | L601: =IFERROR(IF(J601="","",VLOOKUP(J601,Lists!$K$2:$O$61,2,FALSE)),"") | M601: =IFERROR(IF(J601="","",VLOOKUP(J601,Lists!$K$2:$O$61,3,FALSE)),"")

Sheet Dashboard
B2: Dashboard
B3: Everything here is calculated from the Contribution Log. Nothing on this tab needs to be typed.
B5: PRS MERGED | E5: STORIES TOUCHED | H5: STORIES COMPLETE | K5: SELF-REVIEWS
B6: =COUNTA('Contribution Log'!$C$2:$C$601) -> 3 | E6: =SUMPRODUCT((COUNTIF('Contribution Log'!$J$2:$J$601,Lists!$K$3:$K$61)>0)*1) -> 2 | H6: =SUMPRODUCT((COUNTIFS('Contribution Log'!$J$2:$J$601,Lists!$K$3:$K$61,'Contribution Log'!$Q$2:$Q$601,"Yes - story complete")>0)*1) -> 2 | K6: =COUNTIF('Contribution Log'!$E$2:$E$601,"SELF-REVIEW") -> 1
B9: Contribution by member
B10: Member | C10: PRs merged | D10: PRs reviewed | E10: Features | F10: Defect fixes | G10: Tests / docs | H10: Stories completed | I10: First merge | J10: Last merge | K10: Share of PRs
B11: =Lists!$A$2 -> Michael Max | C11: =COUNTIF('Contribution Log'!$C$2:$C$601,Lists!$A$2) -> 0 | D11: =COUNTIF('Contribution Log'!$D$2:$D$601,Lists!$A$2) -> 0 | E11: =COUNTIFS('Contribution Log'!$C$2:$C$601,Lists!$A$2,'Contribution Log'!$H$2:$H$601,"Feature") -> 0 | F11: =COUNTIFS('Contribution Log'!$C$2:$C$601,Lists!$A$2,'Contribution Log'!$H$2:$H$601,"Defect fix") -> 0 | G11: =COUNTIFS('Contribution Log'!$C$2:$C$601,Lists!$A$2,'Contribution Log'!$H$2:$H$601,"Tests")+COUNTIFS('Contribution Log'!$C$2:$C$601,Lists!$A$2,'Contribution Log'!$H$2:$H$601,"Documentation") -> 0 | H11: =SUMPRODUCT((COUNTIFS('Contribution Log'!$J$2:$J$601,Lists!$K$3:$K$61,'Contribution Log'!$C$2:$C$601,Lists!$A$2,'Contribution Log'!$Q$2:$Q$601,"Yes - story complete")>0)*1) -> 0 | I11: =IF(COUNTIF('Contribution Log'!$C$2:$C$601,Lists!$A$2)=0,"",SUMPRODUCT(MIN(('Contribution Log'!$C$2:$C$601=Lists!$A$2)*'Contribution Log'!$A$2:$A$601+('Contribution Log'!$C$2:$C$601<>Lists!$A$2)*300000))) | J11: =IF(COUNTIF('Contribution Log'!$C$2:$C$601,Lists!$A$2)=0,"",SUMPRODUCT(MAX(('Contribution Log'!$C$2:$C$601=Lists!$A$2)*'Contribution Log'!$A$2:$A$601))) | K11: =IFERROR(COUNTIF('Contribution Log'!$C$2:$C$601,Lists!$A$2)/COUNTA('Contribution Log'!$C$2:$C$601),"") -> 0
B12: =Lists!$A$3 -> Parth | C12: =COUNTIF('Contribution Log'!$C$2:$C$601,Lists!$A$3) -> 0 | D12: =COUNTIF('Contribution Log'!$D$2:$D$601,Lists!$A$3) -> 0 | E12: =COUNTIFS('Contribution Log'!$C$2:$C$601,Lists!$A$3,'Contribution Log'!$H$2:$H$601,"Feature") -> 0 | F12: =COUNTIFS('Contribution Log'!$C$2:$C$601,Lists!$A$3,'Contribution Log'!$H$2:$H$601,"Defect fix") -> 0 | G12: =COUNTIFS('Contribution Log'!$C$2:$C$601,Lists!$A$3,'Contribution Log'!$H$2:$H$601,"Tests")+COUNTIFS('Contribution Log'!$C$2:$C$601,Lists!$A$3,'Contribution Log'!$H$2:$H$601,"Documentation") -> 0 | H12: =SUMPRODUCT((COUNTIFS('Contribution Log'!$J$2:$J$601,Lists!$K$3:$K$61,'Contribution Log'!$C$2:$C$601,Lists!$A$3,'Contribution Log'!$Q$2:$Q$601,"Yes - story complete")>0)*1) -> 0 | I12: =IF(COUNTIF('Contribution Log'!$C$2:$C$601,Lists!$A$3)=0,"",SUMPRODUCT(MIN(('Contribution Log'!$C$2:$C$601=Lists!$A$3)*'Contribution Log'!$A$2:$A$601+('Contribution Log'!$C$2:$C$601<>Lists!$A$3)*300000))) | J12: =IF(COUNTIF('Contribution Log'!$C$2:$C$601,Lists!$A$3)=0,"",SUMPRODUCT(MAX(('Contribution Log'!$C$2:$C$601=Lists!$A$3)*'Contribution Log'!$A$2:$A$601))) | K12: =IFERROR(COUNTIF('Contribution Log'!$C$2:$C$601,Lists!$A$3)/COUNTA('Contribution Log'!$C$2:$C$601),"") -> 0
B13: =Lists!$A$4 -> Jingwei Lin | C13: =COUNTIF('Contribution Log'!$C$2:$C$601,Lists!$A$4) -> 1 | D13: =COUNTIF('Contribution Log'!$D$2:$D$601,Lists!$A$4) -> 1 | E13: =COUNTIFS('Contribution Log'!$C$2:$C$601,Lists!$A$4,'Contribution Log'!$H$2:$H$601,"Feature") -> 1 | F13: =COUNTIFS('Contribution Log'!$C$2:$C$601,Lists!$A$4,'Contribution Log'!$H$2:$H$601,"Defect fix") -> 0 | G13: =COUNTIFS('Contribution Log'!$C$2:$C$601,Lists!$A$4,'Contribution Log'!$H$2:$H$601,"Tests")+COUNTIFS('Contribution Log'!$C$2:$C$601,Lists!$A$4,'Contribution Log'!$H$2:$H$601,"Documentation") -> 0 | H13: =SUMPRODUCT((COUNTIFS('Contribution Log'!$J$2:$J$601,Lists!$K$3:$K$61,'Contribution Log'!$C$2:$C$601,Lists!$A$4,'Contribution Log'!$Q$2:$Q$601,"Yes - story complete")>0)*1) -> 1 | I13: =IF(COUNTIF('Contribution Log'!$C$2:$C$601,Lists!$A$4)=0,"",SUMPRODUCT(MIN(('Contribution Log'!$C$2:$C$601=Lists!$A$4)*'Contribution Log'!$A$2:$A$601+('Contribution Log'!$C$2:$C$601<>Lists!$A$4)*300000))) -> 46272 | J13: =IF(COUNTIF('Contribution Log'!$C$2:$C$601,Lists!$A$4)=0,"",SUMPRODUCT(MAX(('Contribution Log'!$C$2:$C$601=Lists!$A$4)*'Contribution Log'!$A$2:$A$601))) -> 46272 | K13: =IFERROR(COUNTIF('Contribution Log'!$C$2:$C$601,Lists!$A$4)/COUNTA('Contribution Log'!$C$2:$C$601),"") -> 0.33333333
B14: =Lists!$A$5 -> Hanchen Wang | C14: =COUNTIF('Contribution Log'!$C$2:$C$601,Lists!$A$5) -> 1 | D14: =COUNTIF('Contribution Log'!$D$2:$D$601,Lists!$A$5) -> 1 | E14: =COUNTIFS('Contribution Log'!$C$2:$C$601,Lists!$A$5,'Contribution Log'!$H$2:$H$601,"Feature") -> 0 | F14: =COUNTIFS('Contribution Log'!$C$2:$C$601,Lists!$A$5,'Contribution Log'!$H$2:$H$601,"Defect fix") -> 0 | G14: =COUNTIFS('Contribution Log'!$C$2:$C$601,Lists!$A$5,'Contribution Log'!$H$2:$H$601,"Tests")+COUNTIFS('Contribution Log'!$C$2:$C$601,Lists!$A$5,'Contribution Log'!$H$2:$H$601,"Documentation") -> 0 | H14: =SUMPRODUCT((COUNTIFS('Contribution Log'!$J$2:$J$601,Lists!$K$3:$K$61,'Contribution Log'!$C$2:$C$601,Lists!$A$5,'Contribution Log'!$Q$2:$Q$601,"Yes - story complete")>0)*1) -> 1 | I14: =IF(COUNTIF('Contribution Log'!$C$2:$C$601,Lists!$A$5)=0,"",SUMPRODUCT(MIN(('Contribution Log'!$C$2:$C$601=Lists!$A$5)*'Contribution Log'!$A$2:$A$601+('Contribution Log'!$C$2:$C$601<>Lists!$A$5)*300000))) -> 46272 | J14: =IF(COUNTIF('Contribution Log'!$C$2:$C$601,Lists!$A$5)=0,"",SUMPRODUCT(MAX(('Contribution Log'!$C$2:$C$601=Lists!$A$5)*'Contribution Log'!$A$2:$A$601))) -> 46272 | K14: =IFERROR(COUNTIF('Contribution Log'!$C$2:$C$601,Lists!$A$5)/COUNTA('Contribution Log'!$C$2:$C$601),"") -> 0.33333333
B15: =Lists!$A$6 -> Yi Geng | C15: =COUNTIF('Contribution Log'!$C$2:$C$601,Lists!$A$6) -> 1 | D15: =COUNTIF('Contribution Log'!$D$2:$D$601,Lists!$A$6) -> 1 | E15: =COUNTIFS('Contribution Log'!$C$2:$C$601,Lists!$A$6,'Contribution Log'!$H$2:$H$601,"Feature") -> 0 | F15: =COUNTIFS('Contribution Log'!$C$2:$C$601,Lists!$A$6,'Contribution Log'!$H$2:$H$601,"Defect fix") -> 0 | G15: =COUNTIFS('Contribution Log'!$C$2:$C$601,Lists!$A$6,'Contribution Log'!$H$2:$H$601,"Tests")+COUNTIFS('Contribution Log'!$C$2:$C$601,Lists!$A$6,'Contribution Log'!$H$2:$H$601,"Documentation") -> 0 | H15: =SUMPRODUCT((COUNTIFS('Contribution Log'!$J$2:$J$601,Lists!$K$3:$K$61,'Contribution Log'!$C$2:$C$601,Lists!$A$6,'Contribution Log'!$Q$2:$Q$601,"Yes - story complete")>0)*1) -> 0 | I15: =IF(COUNTIF('Contribution Log'!$C$2:$C$601,Lists!$A$6)=0,"",SUMPRODUCT(MIN(('Contribution Log'!$C$2:$C$601=Lists!$A$6)*'Contribution Log'!$A$2:$A$601+('Contribution Log'!$C$2:$C$601<>Lists!$A$6)*300000))) -> 46262 | J15: =IF(COUNTIF('Contribution Log'!$C$2:$C$601,Lists!$A$6)=0,"",SUMPRODUCT(MAX(('Contribution Log'!$C$2:$C$601=Lists!$A$6)*'Contribution Log'!$A$2:$A$601))) -> 46262 | K15: =IFERROR(COUNTIF('Contribution Log'!$C$2:$C$601,Lists!$A$6)/COUNTA('Contribution Log'!$C$2:$C$601),"") -> 0.33333333
B16: =Lists!$A$7 -> Dishank Aswal | C16: =COUNTIF('Contribution Log'!$C$2:$C$601,Lists!$A$7) -> 0 | D16: =COUNTIF('Contribution Log'!$D$2:$D$601,Lists!$A$7) -> 0 | E16: =COUNTIFS('Contribution Log'!$C$2:$C$601,Lists!$A$7,'Contribution Log'!$H$2:$H$601,"Feature") -> 0 | F16: =COUNTIFS('Contribution Log'!$C$2:$C$601,Lists!$A$7,'Contribution Log'!$H$2:$H$601,"Defect fix") -> 0 | G16: =COUNTIFS('Contribution Log'!$C$2:$C$601,Lists!$A$7,'Contribution Log'!$H$2:$H$601,"Tests")+COUNTIFS('Contribution Log'!$C$2:$C$601,Lists!$A$7,'Contribution Log'!$H$2:$H$601,"Documentation") -> 0 | H16: =SUMPRODUCT((COUNTIFS('Contribution Log'!$J$2:$J$601,Lists!$K$3:$K$61,'Contribution Log'!$C$2:$C$601,Lists!$A$7,'Contribution Log'!$Q$2:$Q$601,"Yes - story complete")>0)*1) -> 0 | I16: =IF(COUNTIF('Contribution Log'!$C$2:$C$601,Lists!$A$7)=0,"",SUMPRODUCT(MIN(('Contribution Log'!$C$2:$C$601=Lists!$A$7)*'Contribution Log'!$A$2:$A$601+('Contribution Log'!$C$2:$C$601<>Lists!$A$7)*300000))) | J16: =IF(COUNTIF('Contribution Log'!$C$2:$C$601,Lists!$A$7)=0,"",SUMPRODUCT(MAX(('Contribution Log'!$C$2:$C$601=Lists!$A$7)*'Contribution Log'!$A$2:$A$601))) | K16: =IFERROR(COUNTIF('Contribution Log'!$C$2:$C$601,Lists!$A$7)/COUNTA('Contribution Log'!$C$2:$C$601),"") -> 0
B17: =Lists!$A$8 -> Kanishka Kathait | C17: =COUNTIF('Contribution Log'!$C$2:$C$601,Lists!$A$8) -> 0 | D17: =COUNTIF('Contribution Log'!$D$2:$D$601,Lists!$A$8) -> 0 | E17: =COUNTIFS('Contribution Log'!$C$2:$C$601,Lists!$A$8,'Contribution Log'!$H$2:$H$601,"Feature") -> 0 | F17: =COUNTIFS('Contribution Log'!$C$2:$C$601,Lists!$A$8,'Contribution Log'!$H$2:$H$601,"Defect fix") -> 0 | G17: =COUNTIFS('Contribution Log'!$C$2:$C$601,Lists!$A$8,'Contribution Log'!$H$2:$H$601,"Tests")+COUNTIFS('Contribution Log'!$C$2:$C$601,Lists!$A$8,'Contribution Log'!$H$2:$H$601,"Documentation") -> 0 | H17: =SUMPRODUCT((COUNTIFS('Contribution Log'!$J$2:$J$601,Lists!$K$3:$K$61,'Contribution Log'!$C$2:$C$601,Lists!$A$8,'Contribution Log'!$Q$2:$Q$601,"Yes - story complete")>0)*1) -> 0 | I17: =IF(COUNTIF('Contribution Log'!$C$2:$C$601,Lists!$A$8)=0,"",SUMPRODUCT(MIN(('Contribution Log'!$C$2:$C$601=Lists!$A$8)*'Contribution Log'!$A$2:$A$601+('Contribution Log'!$C$2:$C$601<>Lists!$A$8)*300000))) | J17: =IF(COUNTIF('Contribution Log'!$C$2:$C$601,Lists!$A$8)=0,"",SUMPRODUCT(MAX(('Contribution Log'!$C$2:$C$601=Lists!$A$8)*'Contribution Log'!$A$2:$A$601))) | K17: =IFERROR(COUNTIF('Contribution Log'!$C$2:$C$601,Lists!$A$8)/COUNTA('Contribution Log'!$C$2:$C$601),"") -> 0
B18: =Lists!$A$9 -> Tok Tin Chung | C18: =COUNTIF('Contribution Log'!$C$2:$C$601,Lists!$A$9) -> 0 | D18: =COUNTIF('Contribution Log'!$D$2:$D$601,Lists!$A$9) -> 0 | E18: =COUNTIFS('Contribution Log'!$C$2:$C$601,Lists!$A$9,'Contribution Log'!$H$2:$H$601,"Feature") -> 0 | F18: =COUNTIFS('Contribution Log'!$C$2:$C$601,Lists!$A$9,'Contribution Log'!$H$2:$H$601,"Defect fix") -> 0 | G18: =COUNTIFS('Contribution Log'!$C$2:$C$601,Lists!$A$9,'Contribution Log'!$H$2:$H$601,"Tests")+COUNTIFS('Contribution Log'!$C$2:$C$601,Lists!$A$9,'Contribution Log'!$H$2:$H$601,"Documentation") -> 0 | H18: =SUMPRODUCT((COUNTIFS('Contribution Log'!$J$2:$J$601,Lists!$K$3:$K$61,'Contribution Log'!$C$2:$C$601,Lists!$A$9,'Contribution Log'!$Q$2:$Q$601,"Yes - story complete")>0)*1) -> 0 | I18: =IF(COUNTIF('Contribution Log'!$C$2:$C$601,Lists!$A$9)=0,"",SUMPRODUCT(MIN(('Contribution Log'!$C$2:$C$601=Lists!$A$9)*'Contribution Log'!$A$2:$A$601+('Contribution Log'!$C$2:$C$601<>Lists!$A$9)*300000))) | J18: =IF(COUNTIF('Contribution Log'!$C$2:$C$601,Lists!$A$9)=0,"",SUMPRODUCT(MAX(('Contribution Log'!$C$2:$C$601=Lists!$A$9)*'Contribution Log'!$A$2:$A$601))) | K18: =IFERROR(COUNTIF('Contribution Log'!$C$2:$C$601,Lists!$A$9)/COUNTA('Contribution Log'!$C$2:$C$601),"") -> 0
B19: TOTAL | C19: =SUM(C11:C18) -> 3 | D19: =SUM(D11:D18) -> 3 | E19: =SUM(E11:E18) -> 1 | F19: =SUM(F11:F18) -> 0 | G19: =SUM(G11:G18) -> 0 | H19: =SUMPRODUCT((COUNTIFS('Contribution Log'!$J$2:$J$601,Lists!$K$3:$K$61,'Contribution Log'!$Q$2:$Q$601,"Yes - story complete")>0)*1) -> 2
B20: TOTAL counts distinct stories, so it can be lower than the column above if two people finished the same story.
B22: PRs merged per week | H22: Weeks are calculated from the date merged. Blank weeks simply have nothing logged yet.
B23: Week | C23: =Lists!$A$2 -> Michael Max | D23: =Lists!$A$3 -> Parth | E23: =Lists!$A$4 -> Jingwei Lin | F23: =Lists!$A$5 -> Hanchen Wang | G23: =Lists!$A$6 -> Yi Geng | H23: =Lists!$A$7 -> Dishank Aswal | I23: =Lists!$A$8 -> Kanishka Kathait | J23: =Lists!$A$9 -> Tok Tin Chung | K23: Total
B24: W1 | C24: =COUNTIFS('Contribution Log'!$B$2:$B$601,"W1",'Contribution Log'!$C$2:$C$601,Lists!$A$2) -> 0 | D24: =COUNTIFS('Contribution Log'!$B$2:$B$601,"W1",'Contribution Log'!$C$2:$C$601,Lists!$A$3) -> 0 | E24: =COUNTIFS('Contribution Log'!$B$2:$B$601,"W1",'Contribution Log'!$C$2:$C$601,Lists!$A$4) -> 0 | F24: =COUNTIFS('Contribution Log'!$B$2:$B$601,"W1",'Contribution Log'!$C$2:$C$601,Lists!$A$5) -> 0 | G24: =COUNTIFS('Contribution Log'!$B$2:$B$601,"W1",'Contribution Log'!$C$2:$C$601,Lists!$A$6) -> 0 | H24: =COUNTIFS('Contribution Log'!$B$2:$B$601,"W1",'Contribution Log'!$C$2:$C$601,Lists!$A$7) -> 0 | I24: =COUNTIFS('Contribution Log'!$B$2:$B$601,"W1",'Contribution Log'!$C$2:$C$601,Lists!$A$8) -> 0 | J24: =COUNTIFS('Contribution Log'!$B$2:$B$601,"W1",'Contribution Log'!$C$2:$C$601,Lists!$A$9) -> 0 | K24: =COUNTIF('Contribution Log'!$B$2:$B$601,"W1") -> 0
B25: W2 | C25: =COUNTIFS('Contribution Log'!$B$2:$B$601,"W2",'Contribution Log'!$C$2:$C$601,Lists!$A$2) -> 0 | D25: =COUNTIFS('Contribution Log'!$B$2:$B$601,"W2",'Contribution Log'!$C$2:$C$601,Lists!$A$3) -> 0 | E25: =COUNTIFS('Contribution Log'!$B$2:$B$601,"W2",'Contribution Log'!$C$2:$C$601,Lists!$A$4) -> 0 | F25: =COUNTIFS('Contribution Log'!$B$2:$B$601,"W2",'Contribution Log'!$C$2:$C$601,Lists!$A$5) -> 0 | G25: =COUNTIFS('Contribution Log'!$B$2:$B$601,"W2",'Contribution Log'!$C$2:$C$601,Lists!$A$6) -> 0 | H25: =COUNTIFS('Contribution Log'!$B$2:$B$601,"W2",'Contribution Log'!$C$2:$C$601,Lists!$A$7) -> 0 | I25: =COUNTIFS('Contribution Log'!$B$2:$B$601,"W2",'Contribution Log'!$C$2:$C$601,Lists!$A$8) -> 0 | J25: =COUNTIFS('Contribution Log'!$B$2:$B$601,"W2",'Contribution Log'!$C$2:$C$601,Lists!$A$9) -> 0 | K25: =COUNTIF('Contribution Log'!$B$2:$B$601,"W2") -> 0
B26: W3 | C26: =COUNTIFS('Contribution Log'!$B$2:$B$601,"W3",'Contribution Log'!$C$2:$C$601,Lists!$A$2) -> 0 | D26: =COUNTIFS('Contribution Log'!$B$2:$B$601,"W3",'Contribution Log'!$C$2:$C$601,Lists!$A$3) -> 0 | E26: =COUNTIFS('Contribution Log'!$B$2:$B$601,"W3",'Contribution Log'!$C$2:$C$601,Lists!$A$4) -> 0 | F26: =COUNTIFS('Contribution Log'!$B$2:$B$601,"W3",'Contribution Log'!$C$2:$C$601,Lists!$A$5) -> 0 | G26: =COUNTIFS('Contribution Log'!$B$2:$B$601,"W3",'Contribution Log'!$C$2:$C$601,Lists!$A$6) -> 0 | H26: =COUNTIFS('Contribution Log'!$B$2:$B$601,"W3",'Contribution Log'!$C$2:$C$601,Lists!$A$7) -> 0 | I26: =COUNTIFS('Contribution Log'!$B$2:$B$601,"W3",'Contribution Log'!$C$2:$C$601,Lists!$A$8) -> 0 | J26: =COUNTIFS('Contribution Log'!$B$2:$B$601,"W3",'Contribution Log'!$C$2:$C$601,Lists!$A$9) -> 0 | K26: =COUNTIF('Contribution Log'!$B$2:$B$601,"W3") -> 0
B27: W4 | C27: =COUNTIFS('Contribution Log'!$B$2:$B$601,"W4",'Contribution Log'!$C$2:$C$601,Lists!$A$2) -> 0 | D27: =COUNTIFS('Contribution Log'!$B$2:$B$601,"W4",'Contribution Log'!$C$2:$C$601,Lists!$A$3) -> 0 | E27: =COUNTIFS('Contribution Log'!$B$2:$B$601,"W4",'Contribution Log'!$C$2:$C$601,Lists!$A$4) -> 0 | F27: =COUNTIFS('Contribution Log'!$B$2:$B$601,"W4",'Contribution Log'!$C$2:$C$601,Lists!$A$5) -> 0 | G27: =COUNTIFS('Contribution Log'!$B$2:$B$601,"W4",'Contribution Log'!$C$2:$C$601,Lists!$A$6) -> 1 | H27: =COUNTIFS('Contribution Log'!$B$2:$B$601,"W4",'Contribution Log'!$C$2:$C$601,Lists!$A$7) -> 0 | I27: =COUNTIFS('Contribution Log'!$B$2:$B$601,"W4",'Contribution Log'!$C$2:$C$601,Lists!$A$8) -> 0 | J27: =COUNTIFS('Contribution Log'!$B$2:$B$601,"W4",'Contribution Log'!$C$2:$C$601,Lists!$A$9) -> 0 | K27: =COUNTIF('Contribution Log'!$B$2:$B$601,"W4") -> 1
B28: W5 | C28: =COUNTIFS('Contribution Log'!$B$2:$B$601,"W5",'Contribution Log'!$C$2:$C$601,Lists!$A$2) -> 0 | D28: =COUNTIFS('Contribution Log'!$B$2:$B$601,"W5",'Contribution Log'!$C$2:$C$601,Lists!$A$3) -> 0 | E28: =COUNTIFS('Contribution Log'!$B$2:$B$601,"W5",'Contribution Log'!$C$2:$C$601,Lists!$A$4) -> 0 | F28: =COUNTIFS('Contribution Log'!$B$2:$B$601,"W5",'Contribution Log'!$C$2:$C$601,Lists!$A$5) -> 0 | G28: =COUNTIFS('Contribution Log'!$B$2:$B$601,"W5",'Contribution Log'!$C$2:$C$601,Lists!$A$6) -> 0 | H28: =COUNTIFS('Contribution Log'!$B$2:$B$601,"W5",'Contribution Log'!$C$2:$C$601,Lists!$A$7) -> 0 | I28: =COUNTIFS('Contribution Log'!$B$2:$B$601,"W5",'Contribution Log'!$C$2:$C$601,Lists!$A$8) -> 0 | J28: =COUNTIFS('Contribution Log'!$B$2:$B$601,"W5",'Contribution Log'!$C$2:$C$601,Lists!$A$9) -> 0 | K28: =COUNTIF('Contribution Log'!$B$2:$B$601,"W5") -> 0
B29: W6 | C29: =COUNTIFS('Contribution Log'!$B$2:$B$601,"W6",'Contribution Log'!$C$2:$C$601,Lists!$A$2) -> 0 | D29: =COUNTIFS('Contribution Log'!$B$2:$B$601,"W6",'Contribution Log'!$C$2:$C$601,Lists!$A$3) -> 0 | E29: =COUNTIFS('Contribution Log'!$B$2:$B$601,"W6",'Contribution Log'!$C$2:$C$601,Lists!$A$4) -> 1 | F29: =COUNTIFS('Contribution Log'!$B$2:$B$601,"W6",'Contribution Log'!$C$2:$C$601,Lists!$A$5) -> 1 | G29: =COUNTIFS('Contribution Log'!$B$2:$B$601,"W6",'Contribution Log'!$C$2:$C$601,Lists!$A$6) -> 0 | H29: =COUNTIFS('Contribution Log'!$B$2:$B$601,"W6",'Contribution Log'!$C$2:$C$601,Lists!$A$7) -> 0 | I29: =COUNTIFS('Contribution Log'!$B$2:$B$601,"W6",'Contribution Log'!$C$2:$C$601,Lists!$A$8) -> 0 | J29: =COUNTIFS('Contribution Log'!$B$2:$B$601,"W6",'Contribution Log'!$C$2:$C$601,Lists!$A$9) -> 0 | K29: =COUNTIF('Contribution Log'!$B$2:$B$601,"W6") -> 2
B30: W7 | C30: =COUNTIFS('Contribution Log'!$B$2:$B$601,"W7",'Contribution Log'!$C$2:$C$601,Lists!$A$2) -> 0 | D30: =COUNTIFS('Contribution Log'!$B$2:$B$601,"W7",'Contribution Log'!$C$2:$C$601,Lists!$A$3) -> 0 | E30: =COUNTIFS('Contribution Log'!$B$2:$B$601,"W7",'Contribution Log'!$C$2:$C$601,Lists!$A$4) -> 0 | F30: =COUNTIFS('Contribution Log'!$B$2:$B$601,"W7",'Contribution Log'!$C$2:$C$601,Lists!$A$5) -> 0 | G30: =COUNTIFS('Contribution Log'!$B$2:$B$601,"W7",'Contribution Log'!$C$2:$C$601,Lists!$A$6) -> 0 | H30: =COUNTIFS('Contribution Log'!$B$2:$B$601,"W7",'Contribution Log'!$C$2:$C$601,Lists!$A$7) -> 0 | I30: =COUNTIFS('Contribution Log'!$B$2:$B$601,"W7",'Contribution Log'!$C$2:$C$601,Lists!$A$8) -> 0 | J30: =COUNTIFS('Contribution Log'!$B$2:$B$601,"W7",'Contribution Log'!$C$2:$C$601,Lists!$A$9) -> 0 | K30: =COUNTIF('Contribution Log'!$B$2:$B$601,"W7") -> 0
B31: W8 | C31: =COUNTIFS('Contribution Log'!$B$2:$B$601,"W8",'Contribution Log'!$C$2:$C$601,Lists!$A$2) -> 0 | D31: =COUNTIFS('Contribution Log'!$B$2:$B$601,"W8",'Contribution Log'!$C$2:$C$601,Lists!$A$3) -> 0 | E31: =COUNTIFS('Contribution Log'!$B$2:$B$601,"W8",'Contribution Log'!$C$2:$C$601,Lists!$A$4) -> 0 | F31: =COUNTIFS('Contribution Log'!$B$2:$B$601,"W8",'Contribution Log'!$C$2:$C$601,Lists!$A$5) -> 0 | G31: =COUNTIFS('Contribution Log'!$B$2:$B$601,"W8",'Contribution Log'!$C$2:$C$601,Lists!$A$6) -> 0 | H31: =COUNTIFS('Contribution Log'!$B$2:$B$601,"W8",'Contribution Log'!$C$2:$C$601,Lists!$A$7) -> 0 | I31: =COUNTIFS('Contribution Log'!$B$2:$B$601,"W8",'Contribution Log'!$C$2:$C$601,Lists!$A$8) -> 0 | J31: =COUNTIFS('Contribution Log'!$B$2:$B$601,"W8",'Contribution Log'!$C$2:$C$601,Lists!$A$9) -> 0 | K31: =COUNTIF('Contribution Log'!$B$2:$B$601,"W8") -> 0
B32: W9 | C32: =COUNTIFS('Contribution Log'!$B$2:$B$601,"W9",'Contribution Log'!$C$2:$C$601,Lists!$A$2) -> 0 | D32: =COUNTIFS('Contribution Log'!$B$2:$B$601,"W9",'Contribution Log'!$C$2:$C$601,Lists!$A$3) -> 0 | E32: =COUNTIFS('Contribution Log'!$B$2:$B$601,"W9",'Contribution Log'!$C$2:$C$601,Lists!$A$4) -> 0 | F32: =COUNTIFS('Contribution Log'!$B$2:$B$601,"W9",'Contribution Log'!$C$2:$C$601,Lists!$A$5) -> 0 | G32: =COUNTIFS('Contribution Log'!$B$2:$B$601,"W9",'Contribution Log'!$C$2:$C$601,Lists!$A$6) -> 0 | H32: =COUNTIFS('Contribution Log'!$B$2:$B$601,"W9",'Contribution Log'!$C$2:$C$601,Lists!$A$7) -> 0 | I32: =COUNTIFS('Contribution Log'!$B$2:$B$601,"W9",'Contribution Log'!$C$2:$C$601,Lists!$A$8) -> 0 | J32: =COUNTIFS('Contribution Log'!$B$2:$B$601,"W9",'Contribution Log'!$C$2:$C$601,Lists!$A$9) -> 0 | K32: =COUNTIF('Contribution Log'!$B$2:$B$601,"W9") -> 0
B33: W10 | C33: =COUNTIFS('Contribution Log'!$B$2:$B$601,"W10",'Contribution Log'!$C$2:$C$601,Lists!$A$2) -> 0 | D33: =COUNTIFS('Contribution Log'!$B$2:$B$601,"W10",'Contribution Log'!$C$2:$C$601,Lists!$A$3) -> 0 | E33: =COUNTIFS('Contribution Log'!$B$2:$B$601,"W10",'Contribution Log'!$C$2:$C$601,Lists!$A$4) -> 0 | F33: =COUNTIFS('Contribution Log'!$B$2:$B$601,"W10",'Contribution Log'!$C$2:$C$601,Lists!$A$5) -> 0 | G33: =COUNTIFS('Contribution Log'!$B$2:$B$601,"W10",'Contribution Log'!$C$2:$C$601,Lists!$A$6) -> 0 | H33: =COUNTIFS('Contribution Log'!$B$2:$B$601,"W10",'Contribution Log'!$C$2:$C$601,Lists!$A$7) -> 0 | I33: =COUNTIFS('Contribution Log'!$B$2:$B$601,"W10",'Contribution Log'!$C$2:$C$601,Lists!$A$8) -> 0 | J33: =COUNTIFS('Contribution Log'!$B$2:$B$601,"W10",'Contribution Log'!$C$2:$C$601,Lists!$A$9) -> 0 | K33: =COUNTIF('Contribution Log'!$B$2:$B$601,"W10") -> 0
B34: W11 | C34: =COUNTIFS('Contribution Log'!$B$2:$B$601,"W11",'Contribution Log'!$C$2:$C$601,Lists!$A$2) -> 0 | D34: =COUNTIFS('Contribution Log'!$B$2:$B$601,"W11",'Contribution Log'!$C$2:$C$601,Lists!$A$3) -> 0 | E34: =COUNTIFS('Contribution Log'!$B$2:$B$601,"W11",'Contribution Log'!$C$2:$C$601,Lists!$A$4) -> 0 | F34: =COUNTIFS('Contribution Log'!$B$2:$B$601,"W11",'Contribution Log'!$C$2:$C$601,Lists!$A$5) -> 0 | G34: =COUNTIFS('Contribution Log'!$B$2:$B$601,"W11",'Contribution Log'!$C$2:$C$601,Lists!$A$6) -> 0 | H34: =COUNTIFS('Contribution Log'!$B$2:$B$601,"W11",'Contribution Log'!$C$2:$C$601,Lists!$A$7) -> 0 | I34: =COUNTIFS('Contribution Log'!$B$2:$B$601,"W11",'Contribution Log'!$C$2:$C$601,Lists!$A$8) -> 0 | J34: =COUNTIFS('Contribution Log'!$B$2:$B$601,"W11",'Contribution Log'!$C$2:$C$601,Lists!$A$9) -> 0 | K34: =COUNTIF('Contribution Log'!$B$2:$B$601,"W11") -> 0
B35: W12 | C35: =COUNTIFS('Contribution Log'!$B$2:$B$601,"W12",'Contribution Log'!$C$2:$C$601,Lists!$A$2) -> 0 | D35: =COUNTIFS('Contribution Log'!$B$2:$B$601,"W12",'Contribution Log'!$C$2:$C$601,Lists!$A$3) -> 0 | E35: =COUNTIFS('Contribution Log'!$B$2:$B$601,"W12",'Contribution Log'!$C$2:$C$601,Lists!$A$4) -> 0 | F35: =COUNTIFS('Contribution Log'!$B$2:$B$601,"W12",'Contribution Log'!$C$2:$C$601,Lists!$A$5) -> 0 | G35: =COUNTIFS('Contribution Log'!$B$2:$B$601,"W12",'Contribution Log'!$C$2:$C$601,Lists!$A$6) -> 0 | H35: =COUNTIFS('Contribution Log'!$B$2:$B$601,"W12",'Contribution Log'!$C$2:$C$601,Lists!$A$7) -> 0 | I35: =COUNTIFS('Contribution Log'!$B$2:$B$601,"W12",'Contribution Log'!$C$2:$C$601,Lists!$A$8) -> 0 | J35: =COUNTIFS('Contribution Log'!$B$2:$B$601,"W12",'Contribution Log'!$C$2:$C$601,Lists!$A$9) -> 0 | K35: =COUNTIF('Contribution Log'!$B$2:$B$601,"W12") -> 0
B36: W13 | C36: =COUNTIFS('Contribution Log'!$B$2:$B$601,"W13",'Contribution Log'!$C$2:$C$601,Lists!$A$2) -> 0 | D36: =COUNTIFS('Contribution Log'!$B$2:$B$601,"W13",'Contribution Log'!$C$2:$C$601,Lists!$A$3) -> 0 | E36: =COUNTIFS('Contribution Log'!$B$2:$B$601,"W13",'Contribution Log'!$C$2:$C$601,Lists!$A$4) -> 0 | F36: =COUNTIFS('Contribution Log'!$B$2:$B$601,"W13",'Contribution Log'!$C$2:$C$601,Lists!$A$5) -> 0 | G36: =COUNTIFS('Contribution Log'!$B$2:$B$601,"W13",'Contribution Log'!$C$2:$C$601,Lists!$A$6) -> 0 | H36: =COUNTIFS('Contribution Log'!$B$2:$B$601,"W13",'Contribution Log'!$C$2:$C$601,Lists!$A$7) -> 0 | I36: =COUNTIFS('Contribution Log'!$B$2:$B$601,"W13",'Contribution Log'!$C$2:$C$601,Lists!$A$8) -> 0 | J36: =COUNTIFS('Contribution Log'!$B$2:$B$601,"W13",'Contribution Log'!$C$2:$C$601,Lists!$A$9) -> 0 | K36: =COUNTIF('Contribution Log'!$B$2:$B$601,"W13") -> 0
B38: Where the work went | H38: Review health
B39: Area / repo | C39: PRs | E39: Work type | F39: PRs
B40: =Lists!$E$2 -> hej-web (frontend) | C40: =COUNTIF('Contribution Log'!$I$2:$I$601,Lists!$E$2) -> 0 | E40: =Lists!$D$2 -> Feature | F40: =COUNTIF('Contribution Log'!$H$2:$H$601,Lists!$D$2) -> 1 | H40: PRs with a named reviewer | I40: =COUNTIF('Contribution Log'!$E$2:$E$601,"OK") -> 2
B41: =Lists!$E$3 -> hej-api (backend) | C41: =COUNTIF('Contribution Log'!$I$2:$I$601,Lists!$E$3) -> 1 | E41: =Lists!$D$3 -> Defect fix | F41: =COUNTIF('Contribution Log'!$H$2:$H$601,Lists!$D$3) -> 0 | H41: PRs reviewed by their own author | I41: =COUNTIF('Contribution Log'!$E$2:$E$601,"SELF-REVIEW") -> 1
B42: =Lists!$E$4 -> packages/ui | C42: =COUNTIF('Contribution Log'!$I$2:$I$601,Lists!$E$4) -> 0 | E42: =Lists!$D$4 -> Refactor | F42: =COUNTIF('Contribution Log'!$H$2:$H$601,Lists!$D$4) -> 1 | H42: Rows with no reviewer recorded | I42: =SUMPRODUCT(('Contribution Log'!$C$2:$C$601<>"")*('Contribution Log'!$D$2:$D$601="")) -> 0
B43: =Lists!$E$5 -> labeling_ai_assistnat_mvp (AI) | C43: =COUNTIF('Contribution Log'!$I$2:$I$601,Lists!$E$5) -> 0 | E43: =Lists!$D$5 -> Tests | F43: =COUNTIF('Contribution Log'!$H$2:$H$601,Lists!$D$5) -> 0 | H43: Rows with no story linked | I43: =SUMPRODUCT(('Contribution Log'!$C$2:$C$601<>"")*('Contribution Log'!$J$2:$J$601="")) -> 1
B44: =Lists!$E$6 -> Database / schema | C44: =COUNTIF('Contribution Log'!$I$2:$I$601,Lists!$E$6) -> 0 | E44: =Lists!$D$6 -> Documentation | F44: =COUNTIF('Contribution Log'!$H$2:$H$601,Lists!$D$6) -> 0 | H44: Rows missing a plain-English summary | I44: =SUMPRODUCT(('Contribution Log'!$C$2:$C$601<>"")*('Contribution Log'!$P$2:$P$601="")) -> 2
B45: =Lists!$E$7 -> CI / tooling | C45: =COUNTIF('Contribution Log'!$I$2:$I$601,Lists!$E$7) -> 1 | E45: =Lists!$D$7 -> Spike / Research | F45: =COUNTIF('Contribution Log'!$H$2:$H$601,Lists!$D$7) -> 0
B46: =Lists!$E$8 -> Docs / report | C46: =COUNTIF('Contribution Log'!$I$2:$I$601,Lists!$E$8) -> 0 | E46: =Lists!$D$8 -> DevOps / CI | F46: =COUNTIF('Contribution Log'!$H$2:$H$601,Lists!$D$8) -> 1
...

Sheet Jira Board
B2: Jira Board
B3: The CS-57 board, matched to the 59 committed backlog stories. Status and assignees are a snapshot of docs/Jira.csv; PR counts are live from the Contribution Log. Only the nine Owner cells are typed.
B5: WORK ITEMS | D5: IN PROGRESS | F5: IN REVIEW | H5: DONE | J5: IN SPRINT W6 | L5: UNASSIGNED
B6: 73 | D6: 17 | F6: 1 | H6: 1 | J6: 21 | L6: 55
B8: Who owns what | H8: Fill in the nine Owner cells once. This is the only typing on this tab.
B9: # | C9: Work bundle | D9: Owner | E9: What it covers | G9: Stories | H9: To do | I9: Doing | J9: Done | K9: PRs
B10: 1 | C10: AI task queue | D10: Parth | E10: Task queue with progress bar; completed / failed / retry | G10: =COUNTIF(Lists!$X$3:$X$61,$C10) -> 1 | H10: =COUNTIFS(Lists!$X$3:$X$61,$C10,Lists!$Y$3:$Y$61,"To Do")+COUNTIFS(Lists!$X$3:$X$61,$C10,Lists!$Y$3:$Y$61,"Not on board") -> 1 | I10: =COUNTIFS(Lists!$X$3:$X$61,$C10,Lists!$Y$3:$Y$61,"In progress") -> 0 | J10: =COUNTIFS(Lists!$X$3:$X$61,$C10,Lists!$Y$3:$Y$61,"Done") -> 0 | K10: =SUMPRODUCT((Lists!$X$3:$X$61=$C10)*COUNTIF('Contribution Log'!$J$2:$J$601,Lists!$K$3:$K$61)) -> 0
B11: 2 | C11: AI provider & failures | D11: Yi Geng | E11: Annotation failure and the fake bounding-box fallback; integrate labeling_ai_assistnat_mvp | G11: =COUNTIF(Lists!$X$3:$X$61,$C11) -> 1 | H11: =COUNTIFS(Lists!$X$3:$X$61,$C11,Lists!$Y$3:$Y$61,"To Do")+COUNTIFS(Lists!$X$3:$X$61,$C11,Lists!$Y$3:$Y$61,"Not on board") -> 0 | I11: =COUNTIFS(Lists!$X$3:$X$61,$C11,Lists!$Y$3:$Y$61,"In progress") -> 1 | J11: =COUNTIFS(Lists!$X$3:$X$61,$C11,Lists!$Y$3:$Y$61,"Done") -> 0 | K11: =SUMPRODUCT((Lists!$X$3:$X$61=$C11)*COUNTIF('Contribution Log'!$J$2:$J$601,Lists!$K$3:$K$61)) -> 0
B12: 3 | C12: Project setup & status UI | D12: Hanchen Wang | E12: Project / policy / task update, dataset upload, status page | G12: =COUNTIF(Lists!$X$3:$X$61,$C12) -> 7 | H12: =COUNTIFS(Lists!$X$3:$X$61,$C12,Lists!$Y$3:$Y$61,"To Do")+COUNTIFS(Lists!$X$3:$X$61,$C12,Lists!$Y$3:$Y$61,"Not on board") -> 6 | I12: =COUNTIFS(Lists!$X$3:$X$61,$C12,Lists!$Y$3:$Y$61,"In progress") -> 1 | J12: =COUNTIFS(Lists!$X$3:$X$61,$C12,Lists!$Y$3:$Y$61,"Done") -> 0 | K12: =SUMPRODUCT((Lists!$X$3:$X$61=$C12)*COUNTIF('Contribution Log'!$J$2:$J$601,Lists!$K$3:$K$61)) -> 0
B13: 4 | C13: Task & item backend | E13: Illegal item status, cross-project writes, non-transactional task registration, missing transition out of draft, task-item routes and services | G13: =COUNTIF(Lists!$X$3:$X$61,$C13) -> 4 | H13: =COUNTIFS(Lists!$X$3:$X$61,$C13,Lists!$Y$3:$Y$61,"To Do")+COUNTIFS(Lists!$X$3:$X$61,$C13,Lists!$Y$3:$Y$61,"Not on board") -> 1 | I13: =COUNTIFS(Lists!$X$3:$X$61,$C13,Lists!$Y$3:$Y$61,"In progress") -> 3 | J13: =COUNTIFS(Lists!$X$3:$X$61,$C13,Lists!$Y$3:$Y$61,"Done") -> 0 | K13: =SUMPRODUCT((Lists!$X$3:$X$61=$C13)*COUNTIF('Contribution Log'!$J$2:$J$601,Lists!$K$3:$K$61)) -> 0
B14: 5 | C14: Annotation page & judgement | E14: Annotation page with judgement feedback or justification | G14: =COUNTIF(Lists!$X$3:$X$61,$C14) -> 6 | H14: =COUNTIFS(Lists!$X$3:$X$61,$C14,Lists!$Y$3:$Y$61,"To Do")+COUNTIFS(Lists!$X$3:$X$61,$C14,Lists!$Y$3:$Y$61,"Not on board") -> 4 | I14: =COUNTIFS(Lists!$X$3:$X$61,$C14,Lists!$Y$3:$Y$61,"In progress") -> 2 | J14: =COUNTIFS(Lists!$X$3:$X$61,$C14,Lists!$Y$3:$Y$61,"Done") -> 0 | K14: =SUMPRODUCT((Lists!$X$3:$X$61=$C14)*COUNTIF('Contribution Log'!$J$2:$J$601,Lists!$K$3:$K$61)) -> 0
B15: 6 | C15: Draft ownership & verdict | E15: Finalised annotation overwrite, draft ownership, judgement verdict and feedback | G15: =COUNTIF(Lists!$X$3:$X$61,$C15) -> 3 | H15: =COUNTIFS(Lists!$X$3:$X$61,$C15,Lists!$Y$3:$Y$61,"To Do")+COUNTIFS(Lists!$X$3:$X$61,$C15,Lists!$Y$3:$Y$61,"Not on board") -> 1 | I15: =COUNTIFS(Lists!$X$3:$X$61,$C15,Lists!$Y$3:$Y$61,"In progress") -> 2 | J15: =COUNTIFS(Lists!$X$3:$X$61,$C15,Lists!$Y$3:$Y$61,"Done") -> 0 | K15: =SUMPRODUCT((Lists!$X$3:$X$61=$C15)*COUNTIF('Contribution Log'!$J$2:$J$601,Lists!$K$3:$K$61)) -> 0
B16: 7 | C16: Review, permissions & dispute | E16: Reviewer correction, avoid self-review, review action, permission and dispute | G16: =COUNTIF(Lists!$X$3:$X$61,$C16) -> 8 | H16: =COUNTIFS(Lists!$X$3:$X$61,$C16,Lists!$Y$3:$Y$61,"To Do")+COUNTIFS(Lists!$X$3:$X$61,$C16,Lists!$Y$3:$Y$61,"Not on board") -> 6 | I16: =COUNTIFS(Lists!$X$3:$X$61,$C16,Lists!$Y$3:$Y$61,"In progress") -> 2 | J16: =COUNTIFS(Lists!$X$3:$X$61,$C16,Lists!$Y$3:$Y$61,"Done") -> 0 | K16: =SUMPRODUCT((Lists!$X$3:$X$61=$C16)*COUNTIF('Contribution Log'!$J$2:$J$601,Lists!$K$3:$K$61)) -> 1
B17: 8 | C17: Audit & history | E17: Audit and history | G17: =COUNTIF(Lists!$X$3:$X$61,$C17) -> 4 | H17: =COUNTIFS(Lists!$X$3:$X$61,$C17,Lists!$Y$3:$Y$61,"To Do")+COUNTIFS(Lists!$X$3:$X$61,$C17,Lists!$Y$3:$Y$61,"Not on board") -> 4 | I17: =COUNTIFS(Lists!$X$3:$X$61,$C17,Lists!$Y$3:$Y$61,"In progress") -> 0 | J17: =COUNTIFS(Lists!$X$3:$X$61,$C17,Lists!$Y$3:$Y$61,"Done") -> 0 | K17: =SUMPRODUCT((Lists!$X$3:$X$61=$C17)*COUNTIF('Contribution Log'!$J$2:$J$601,Lists!$K$3:$K$61)) -> 0
B18: 9 | C18: Release & export | E18: Release and export | G18: =COUNTIF(Lists!$X$3:$X$61,$C18) -> 5 | H18: =COUNTIFS(Lists!$X$3:$X$61,$C18,Lists!$Y$3:$Y$61,"To Do")+COUNTIFS(Lists!$X$3:$X$61,$C18,Lists!$Y$3:$Y$61,"Not on board") -> 5 | I18: =COUNTIFS(Lists!$X$3:$X$61,$C18,Lists!$Y$3:$Y$61,"In progress") -> 0 | J18: =COUNTIFS(Lists!$X$3:$X$61,$C18,Lists!$Y$3:$Y$61,"Done") -> 0 | K18: =SUMPRODUCT((Lists!$X$3:$X$61=$C18)*COUNTIF('Contribution Log'!$J$2:$J$601,Lists!$K$3:$K$61)) -> 0
B19: - | C19: Unallocated | E19: Not in the allocation document. Assign these before they become a surprise. | G19: =COUNTIF(Lists!$X$3:$X$61,$C19) -> 20 | H19: =COUNTIFS(Lists!$X$3:$X$61,$C19,Lists!$Y$3:$Y$61,"To Do")+COUNTIFS(Lists!$X$3:$X$61,$C19,Lists!$Y$3:$Y$61,"Not on board") -> 9 | I19: =COUNTIFS(Lists!$X$3:$X$61,$C19,Lists!$Y$3:$Y$61,"In progress") -> 4 | J19: =COUNTIFS(Lists!$X$3:$X$61,$C19,Lists!$Y$3:$Y$61,"Done") -> 1 | K19: =SUMPRODUCT((Lists!$X$3:$X$61=$C19)*COUNTIF('Contribution Log'!$J$2:$J$601,Lists!$K$3:$K$61)) -> 1
B21: Committed scope | H21: Done counts what the board says is done. A story with no ticket cannot be done. | I21: By epic
B22: Priority | C22: Stories | D22: Done | E22: Doing | F22: On board | G22: % done | I22: Epic | J22: Stories | K22: Done
B23: P0 - committed core | C23: =COUNTIF(Lists!$M$3:$M$61,"P0") -> 35 | D23: =COUNTIFS(Lists!$M$3:$M$61,"P0",Lists!$Y$3:$Y$61,"Done") -> 1 | E23: =COUNTIFS(Lists!$M$3:$M$61,"P0",Lists!$Y$3:$Y$61,"In progress") -> 12 | F23: =COUNTIF(Lists!$M$3:$M$61,"P0")-COUNTIFS(Lists!$M$3:$M$61,"P0",Lists!$Y$3:$Y$61,"Not on board")-COUNTIFS(Lists!$M$3:$M$61,"P0",Lists!$Y$3:$Y$61,"Dropped") -> 32 | G23: =IFERROR(D23/C23,"") -> 0.028571429 | I23: A - Trustworthy Foundations | J23: =COUNTIF(Lists!$L$3:$L$61,"A") -> 5 | K23: =COUNTIFS(Lists!$L$3:$L$61,"A",Lists!$Y$3:$Y$61,"Done") -> 1
B24: P1 | C24: =COUNTIF(Lists!$M$3:$M$61,"P1") -> 20 | D24: =COUNTIFS(Lists!$M$3:$M$61,"P1",Lists!$Y$3:$Y$61,"Done") -> 0 | E24: =COUNTIFS(Lists!$M$3:$M$61,"P1",Lists!$Y$3:$Y$61,"In progress") -> 3 | F24: =COUNTIF(Lists!$M$3:$M$61,"P1")-COUNTIFS(Lists!$M$3:$M$61,"P1",Lists!$Y$3:$Y$61,"Not on board")-COUNTIFS(Lists!$M$3:$M$61,"P1",Lists!$Y$3:$Y$61,"Dropped") -> 17 | G24: =IFERROR(D24/C24,"") -> 0 | I24: B - Setting Up Work | J24: =COUNTIF(Lists!$L$3:$L$61,"B") -> 6 | K24: =COUNTIFS(Lists!$L$3:$L$61,"B",Lists!$Y$3:$Y$61,"Done") -> 0
B25: P2 - nice to have | C25: =COUNTIF(Lists!$M$3:$M$61,"P2") -> 4 | D25: =COUNTIFS(Lists!$M$3:$M$61,"P2",Lists!$Y$3:$Y$61,"Done") -> 0 | E25: =COUNTIFS(Lists!$M$3:$M$61,"P2",Lists!$Y$3:$Y$61,"In progress") -> 0 | F25: =COUNTIF(Lists!$M$3:$M$61,"P2")-COUNTIFS(Lists!$M$3:$M$61,"P2",Lists!$Y$3:$Y$61,"Not on board")-COUNTIFS(Lists!$M$3:$M$61,"P2",Lists!$Y$3:$Y$61,"Dropped") -> 4 | G25: =IFERROR(D25/C25,"") -> 0 | I25: C - AI-Assisted First Pass | J25: =COUNTIF(Lists!$L$3:$L$61,"C") -> 5 | K25: =COUNTIFS(Lists!$L$3:$L$61,"C",Lists!$Y$3:$Y$61,"Done") -> 0
B26: All stories | C26: 59 | D26: =COUNTIF(Lists!$Y$3:$Y$61,"Done") -> 1 | E26: =COUNTIF(Lists!$Y$3:$Y$61,"In progress") -> 15 | F26: =COUNTA(Lists!$K$3:$K$61)-COUNTIF(Lists!$Y$3:$Y$61,"Not on board")-COUNTIF(Lists!$Y$3:$Y$61,"Dropped") -> 53 | G26: =IFERROR(D26/C26,"") -> 0.016949153 | I26: D - Review & Cross-Validation | J26: =COUNTIF(Lists!$L$3:$L$61,"D") -> 8 | K26: =COUNTIFS(Lists!$L$3:$L$61,"D",Lists!$Y$3:$Y$61,"Done") -> 0
I27: E - Disagreement & Dispute | J27: =COUNTIF(Lists!$L$3:$L$61,"E") -> 6 | K27: =COUNTIFS(Lists!$L$3:$L$61,"E",Lists!$Y$3:$Y$61,"Done") -> 0
I28: F - Provenance & History | J28: =COUNTIF(Lists!$L$3:$L$61,"F") -> 5 | K28: =COUNTIFS(Lists!$L$3:$L$61,"F",Lists!$Y$3:$Y$61,"Done") -> 0
I29: G - Roles, Permissions & Organisations | J29: =COUNTIF(Lists!$L$3:$L$61,"G") -> 5 | K29: =COUNTIFS(Lists!$L$3:$L$61,"G",Lists!$Y$3:$Y$61,"Done") -> 0
I30: H - Release & Export | J30: =COUNTIF(Lists!$L$3:$L$61,"H") -> 6 | K30: =COUNTIFS(Lists!$L$3:$L$61,"H",Lists!$Y$3:$Y$61,"Done") -> 0
I31: I - Evaluation | J31: =COUNTIF(Lists!$L$3:$L$61,"I") -> 5 | K31: =COUNTIFS(Lists!$L$3:$L$61,"I",Lists!$Y$3:$Y$61,"Done") -> 0
I32: J - Organisations & Dashboard | J32: =COUNTIF(Lists!$L$3:$L$61,"J") -> 4 | K32: =COUNTIFS(Lists!$L$3:$L$61,"J",Lists!$Y$3:$Y$61,"Done") -> 0
I33: K - Evidence & Handover | J33: =COUNTIF(Lists!$L$3:$L$61,"K") -> 4 | K33: =COUNTIFS(Lists!$L$3:$L$61,"K",Lists!$Y$3:$Y$61,"Done") -> 0
B35: Waiting for a ticket | H35: Committed stories with nothing on the board. Nobody is working on these, because there is nothing to pick up.
B36: None | C36: Every committed story that is not dropped has at least one ticket on the board.
B37: Dropped | C37: 6 stories the team dropped, so no ticket is expected: A1 A5 K1 K2 K3 K4
B39: Workload by person | H39: Issues assigned on the board, beside PRs actually logged. Both count the same eight people.
B40: Member | C40: Assigned | D40: To do | E40: Doing | F40: In review | G40: Done | H40: In sprint | I40: Bundles touched | J40: PRs logged | K40: Reviews
B41: =Lists!$A$2 -> Michael Max | C41: 2 | D41: 0 | E41: 2 | F41: 0 | G41: 0 | H41: 2 | I41: AI provider & failures | J41: =COUNTIF('Contribution Log'!$C$2:$C$601,Lists!$A$2) -> 0 | K41: =COUNTIF('Contribution Log'!$D$2:$D$601,Lists!$A$2) -> 0
B42: =Lists!$A$3 -> Parth | C42: 2 | D42: 0 | E42: 2 | F42: 0 | G42: 0 | H42: 2 | I42: Annotation page & judgement | J42: =COUNTIF('Contribution Log'!$C$2:$C$601,Lists!$A$3) -> 0 | K42: =COUNTIF('Contribution Log'!$D$2:$D$601,Lists!$A$3) -> 0
B43: =Lists!$A$4 -> Jingwei Lin | C43: 3 | D43: 0 | E43: 2 | F43: 1 | G43: 0 | H43: 3 | I43: Review, permissions & dispute, Task & item backend | J43: =COUNTIF('Contribution Log'!$C$2:$C$601,Lists!$A$4) -> 1 | K43: =COUNTIF('Contribution Log'!$D$2:$D$601,Lists!$A$4) -> 1
B44: =Lists!$A$5 -> Hanchen Wang | C44: 5 | D44: 0 | E44: 4 | F44: 0 | G44: 1 | H44: 5 | I44: Draft ownership & verdict, Unallocated | J44: =COUNTIF('Contribution Log'!$C$2:$C$601,Lists!$A$5) -> 1 | K44: =COUNTIF('Contribution Log'!$D$2:$D$601,Lists!$A$5) -> 1
B45: =Lists!$A$6 -> Yi Geng | C45: 2 | D45: 0 | E45: 2 | F45: 0 | G45: 0 | H45: 2 | I45: Draft ownership & verdict, Unallocated | J45: =COUNTIF('Contribution Log'!$C$2:$C$601,Lists!$A$6) -> 1 | K45: =COUNTIF('Contribution Log'!$D$2:$D$601,Lists!$A$6) -> 1
B46: =Lists!$A$7 -> Dishank Aswal | C46: 1 | D46: 0 | E46: 1 | F46: 0 | G46: 0 | H46: 1 | I46: Task & item backend | J46: =COUNTIF('Contribution Log'!$C$2:$C$601,Lists!$A$7) -> 0 | K46: =COUNTIF('Contribution Log'!$D$2:$D$601,Lists!$A$7) -> 0
...

Sheet Client Report
B2: Client Report
B3: Set the two dates below. Everything else recalculates for that period - ready to paste into the Status Checking form or the weekly client meeting.
B5: Reporting period starts | C5: 46260 | D5: <- type the two dates here
B6: Reporting period ends | C6: 46281
B8: This period at a glance | E8: Delivery by epic, this period
B9: PRs merged | C9: =COUNTIFS('Contribution Log'!$A$2:$A$601,">="&$C$5,'Contribution Log'!$A$2:$A$601,"<="&$C$6) -> 3 | E9: Epic | F9: PRs | G9: Stories done
B10: Members who merged | C10: =SUMPRODUCT((COUNTIFS('Contribution Log'!$A$2:$A$601,">="&$C$5,'Contribution Log'!$A$2:$A$601,"<="&$C$6,'Contribution Log'!$C$2:$C$601,Lists!$A$2:$A$9)>0)*1) -> 3 | E10: ="A - Trustworthy Foundations" -> A - Trustworthy Foundations | F10: =COUNTIFS('Contribution Log'!$A$2:$A$601,">="&$C$5,'Contribution Log'!$A$2:$A$601,"<="&$C$6,'Contribution Log'!$L$2:$L$601,Lists!$H$2) -> 1 | G10: =SUMPRODUCT((COUNTIFS('Contribution Log'!$A$2:$A$601,">="&$C$5,'Contribution Log'!$A$2:$A$601,"<="&$C$6,'Contribution Log'!$L$2:$L$601,Lists!$H$2,'Contribution Log'!$J$2:$J$601,Lists!$K$3:$K$61,'Contribution Log'!$Q$2:$Q$601,"Yes - story complete")>0)*1) -> 1
B11: Stories completed | C11: =SUMPRODUCT((COUNTIFS('Contribution Log'!$A$2:$A$601,">="&$C$5,'Contribution Log'!$A$2:$A$601,"<="&$C$6,'Contribution Log'!$J$2:$J$601,Lists!$K$3:$K$61,'Contribution Log'!$Q$2:$Q$601,"Yes - story complete")>0)*1) -> 2 | E11: ="B - Setting Up Work" -> B - Setting Up Work | F11: =COUNTIFS('Contribution Log'!$A$2:$A$601,">="&$C$5,'Contribution Log'!$A$2:$A$601,"<="&$C$6,'Contribution Log'!$L$2:$L$601,Lists!$H$3) -> 0 | G11: =SUMPRODUCT((COUNTIFS('Contribution Log'!$A$2:$A$601,">="&$C$5,'Contribution Log'!$A$2:$A$601,"<="&$C$6,'Contribution Log'!$L$2:$L$601,Lists!$H$3,'Contribution Log'!$J$2:$J$601,Lists!$K$3:$K$61,'Contribution Log'!$Q$2:$Q$601,"Yes - story complete")>0)*1) -> 0
B12: Defect-fix PRs | C12: =COUNTIFS('Contribution Log'!$A$2:$A$601,">="&$C$5,'Contribution Log'!$A$2:$A$601,"<="&$C$6,'Contribution Log'!$H$2:$H$601,"Defect fix") -> 0 | E12: ="C - AI-Assisted First Pass" -> C - AI-Assisted First Pass | F12: =COUNTIFS('Contribution Log'!$A$2:$A$601,">="&$C$5,'Contribution Log'!$A$2:$A$601,"<="&$C$6,'Contribution Log'!$L$2:$L$601,Lists!$H$4) -> 0 | G12: =SUMPRODUCT((COUNTIFS('Contribution Log'!$A$2:$A$601,">="&$C$5,'Contribution Log'!$A$2:$A$601,"<="&$C$6,'Contribution Log'!$L$2:$L$601,Lists!$H$4,'Contribution Log'!$J$2:$J$601,Lists!$K$3:$K$61,'Contribution Log'!$Q$2:$Q$601,"Yes - story complete")>0)*1) -> 0
B13: Feature PRs | C13: =COUNTIFS('Contribution Log'!$A$2:$A$601,">="&$C$5,'Contribution Log'!$A$2:$A$601,"<="&$C$6,'Contribution Log'!$H$2:$H$601,"Feature") -> 1 | E13: ="D - Review & Cross-Validation" -> D - Review & Cross-Validation | F13: =COUNTIFS('Contribution Log'!$A$2:$A$601,">="&$C$5,'Contribution Log'!$A$2:$A$601,"<="&$C$6,'Contribution Log'!$L$2:$L$601,Lists!$H$5) -> 0 | G13: =SUMPRODUCT((COUNTIFS('Contribution Log'!$A$2:$A$601,">="&$C$5,'Contribution Log'!$A$2:$A$601,"<="&$C$6,'Contribution Log'!$L$2:$L$601,Lists!$H$5,'Contribution Log'!$J$2:$J$601,Lists!$K$3:$K$61,'Contribution Log'!$Q$2:$Q$601,"Yes - story complete")>0)*1) -> 0
B14: PRs reviewed by a second person | C14: =COUNTIFS('Contribution Log'!$A$2:$A$601,">="&$C$5,'Contribution Log'!$A$2:$A$601,"<="&$C$6,'Contribution Log'!$E$2:$E$601,"OK") -> 2 | E14: ="E - Disagreement & Dispute" -> E - Disagreement & Dispute | F14: =COUNTIFS('Contribution Log'!$A$2:$A$601,">="&$C$5,'Contribution Log'!$A$2:$A$601,"<="&$C$6,'Contribution Log'!$L$2:$L$601,Lists!$H$6) -> 0 | G14: =SUMPRODUCT((COUNTIFS('Contribution Log'!$A$2:$A$601,">="&$C$5,'Contribution Log'!$A$2:$A$601,"<="&$C$6,'Contribution Log'!$L$2:$L$601,Lists!$H$6,'Contribution Log'!$J$2:$J$601,Lists!$K$3:$K$61,'Contribution Log'!$Q$2:$Q$601,"Yes - story complete")>0)*1) -> 0
E15: ="F - Provenance & History" -> F - Provenance & History | F15: =COUNTIFS('Contribution Log'!$A$2:$A$601,">="&$C$5,'Contribution Log'!$A$2:$A$601,"<="&$C$6,'Contribution Log'!$L$2:$L$601,Lists!$H$7) -> 0 | G15: =SUMPRODUCT((COUNTIFS('Contribution Log'!$A$2:$A$601,">="&$C$5,'Contribution Log'!$A$2:$A$601,"<="&$C$6,'Contribution Log'!$L$2:$L$601,Lists!$H$7,'Contribution Log'!$J$2:$J$601,Lists!$K$3:$K$61,'Contribution Log'!$Q$2:$Q$601,"Yes - story complete")>0)*1) -> 0
E16: ="G - Roles, Permissions & Organisations" -> G - Roles, Permissions & Organisations | F16: =COUNTIFS('Contribution Log'!$A$2:$A$601,">="&$C$5,'Contribution Log'!$A$2:$A$601,"<="&$C$6,'Contribution Log'!$L$2:$L$601,Lists!$H$8) -> 1 | G16: =SUMPRODUCT((COUNTIFS('Contribution Log'!$A$2:$A$601,">="&$C$5,'Contribution Log'!$A$2:$A$601,"<="&$C$6,'Contribution Log'!$L$2:$L$601,Lists!$H$8,'Contribution Log'!$J$2:$J$601,Lists!$K$3:$K$61,'Contribution Log'!$Q$2:$Q$601,"Yes - story complete")>0)*1) -> 1
E17: ="H - Release & Export" -> H - Release & Export | F17: =COUNTIFS('Contribution Log'!$A$2:$A$601,">="&$C$5,'Contribution Log'!$A$2:$A$601,"<="&$C$6,'Contribution Log'!$L$2:$L$601,Lists!$H$9) -> 0 | G17: =SUMPRODUCT((COUNTIFS('Contribution Log'!$A$2:$A$601,">="&$C$5,'Contribution Log'!$A$2:$A$601,"<="&$C$6,'Contribution Log'!$L$2:$L$601,Lists!$H$9,'Contribution Log'!$J$2:$J$601,Lists!$K$3:$K$61,'Contribution Log'!$Q$2:$Q$601,"Yes - story complete")>0)*1) -> 0
B18: Individual contribution, this period | E18: ="I - Evaluation" -> I - Evaluation | F18: =COUNTIFS('Contribution Log'!$A$2:$A$601,">="&$C$5,'Contribution Log'!$A$2:$A$601,"<="&$C$6,'Contribution Log'!$L$2:$L$601,Lists!$H$10) -> 0 | G18: =SUMPRODUCT((COUNTIFS('Contribution Log'!$A$2:$A$601,">="&$C$5,'Contribution Log'!$A$2:$A$601,"<="&$C$6,'Contribution Log'!$L$2:$L$601,Lists!$H$10,'Contribution Log'!$J$2:$J$601,Lists!$K$3:$K$61,'Contribution Log'!$Q$2:$Q$601,"Yes - story complete")>0)*1) -> 0
B19: Member | C19: PRs | D19: Reviews given | E19: Stories completed | F19: Main area | G19: What they delivered (write this before the client meeting)
B20: =Lists!$A$2 -> Michael Max | C20: =COUNTIFS('Contribution Log'!$A$2:$A$601,">="&$C$5,'Contribution Log'!$A$2:$A$601,"<="&$C$6,'Contribution Log'!$C$2:$C$601,Lists!$A$2) -> 0 | D20: =COUNTIFS('Contribution Log'!$A$2:$A$601,">="&$C$5,'Contribution Log'!$A$2:$A$601,"<="&$C$6,'Contribution Log'!$D$2:$D$601,Lists!$A$2) -> 0 | E20: =SUMPRODUCT((COUNTIFS('Contribution Log'!$A$2:$A$601,">="&$C$5,'Contribution Log'!$A$2:$A$601,"<="&$C$6,'Contribution Log'!$C$2:$C$601,Lists!$A$2,'Contribution Log'!$J$2:$J$601,Lists!$K$3:$K$61,'Contribution Log'!$Q$2:$Q$601,"Yes - story complete")>0)*1) -> 0 | F20: =COUNTIFS('Contribution Log'!$A$2:$A$601,">="&$C$5,'Contribution Log'!$A$2:$A$601,"<="&$C$6,'Contribution Log'!$L$2:$L$601,Lists!$H$12) -> 0 | G20: =SUMPRODUCT((COUNTIFS('Contribution Log'!$A$2:$A$601,">="&$C$5,'Contribution Log'!$A$2:$A$601,"<="&$C$6,'Contribution Log'!$L$2:$L$601,Lists!$H$12,'Contribution Log'!$J$2:$J$601,Lists!$K$3:$K$61,'Contribution Log'!$Q$2:$Q$601,"Yes - story complete")>0)*1) -> 0
B21: =Lists!$A$3 -> Parth | C21: =COUNTIFS('Contribution Log'!$A$2:$A$601,">="&$C$5,'Contribution Log'!$A$2:$A$601,"<="&$C$6,'Contribution Log'!$C$2:$C$601,Lists!$A$3) -> 0 | D21: =COUNTIFS('Contribution Log'!$A$2:$A$601,">="&$C$5,'Contribution Log'!$A$2:$A$601,"<="&$C$6,'Contribution Log'!$D$2:$D$601,Lists!$A$3) -> 0 | E21: =SUMPRODUCT((COUNTIFS('Contribution Log'!$A$2:$A$601,">="&$C$5,'Contribution Log'!$A$2:$A$601,"<="&$C$6,'Contribution Log'!$C$2:$C$601,Lists!$A$3,'Contribution Log'!$J$2:$J$601,Lists!$K$3:$K$61,'Contribution Log'!$Q$2:$Q$601,"Yes - story complete")>0)*1) -> 0
B22: =Lists!$A$4 -> Jingwei Lin | C22: =COUNTIFS('Contribution Log'!$A$2:$A$601,">="&$C$5,'Contribution Log'!$A$2:$A$601,"<="&$C$6,'Contribution Log'!$C$2:$C$601,Lists!$A$4) -> 1 | D22: =COUNTIFS('Contribution Log'!$A$2:$A$601,">="&$C$5,'Contribution Log'!$A$2:$A$601,"<="&$C$6,'Contribution Log'!$D$2:$D$601,Lists!$A$4) -> 1 | E22: =SUMPRODUCT((COUNTIFS('Contribution Log'!$A$2:$A$601,">="&$C$5,'Contribution Log'!$A$2:$A$601,"<="&$C$6,'Contribution Log'!$C$2:$C$601,Lists!$A$4,'Contribution Log'!$J$2:$J$601,Lists!$K$3:$K$61,'Contribution Log'!$Q$2:$Q$601,"Yes - story complete")>0)*1) -> 1
B23: =Lists!$A$5 -> Hanchen Wang | C23: =COUNTIFS('Contribution Log'!$A$2:$A$601,">="&$C$5,'Contribution Log'!$A$2:$A$601,"<="&$C$6,'Contribution Log'!$C$2:$C$601,Lists!$A$5) -> 1 | D23: =COUNTIFS('Contribution Log'!$A$2:$A$601,">="&$C$5,'Contribution Log'!$A$2:$A$601,"<="&$C$6,'Contribution Log'!$D$2:$D$601,Lists!$A$5) -> 1 | E23: =SUMPRODUCT((COUNTIFS('Contribution Log'!$A$2:$A$601,">="&$C$5,'Contribution Log'!$A$2:$A$601,"<="&$C$6,'Contribution Log'!$C$2:$C$601,Lists!$A$5,'Contribution Log'!$J$2:$J$601,Lists!$K$3:$K$61,'Contribution Log'!$Q$2:$Q$601,"Yes - story complete")>0)*1) -> 1
B24: =Lists!$A$6 -> Yi Geng | C24: =COUNTIFS('Contribution Log'!$A$2:$A$601,">="&$C$5,'Contribution Log'!$A$2:$A$601,"<="&$C$6,'Contribution Log'!$C$2:$C$601,Lists!$A$6) -> 1 | D24: =COUNTIFS('Contribution Log'!$A$2:$A$601,">="&$C$5,'Contribution Log'!$A$2:$A$601,"<="&$C$6,'Contribution Log'!$D$2:$D$601,Lists!$A$6) -> 1 | E24: =SUMPRODUCT((COUNTIFS('Contribution Log'!$A$2:$A$601,">="&$C$5,'Contribution Log'!$A$2:$A$601,"<="&$C$6,'Contribution Log'!$C$2:$C$601,Lists!$A$6,'Contribution Log'!$J$2:$J$601,Lists!$K$3:$K$61,'Contribution Log'!$Q$2:$Q$601,"Yes - story complete")>0)*1) -> 0
B25: =Lists!$A$7 -> Dishank Aswal | C25: =COUNTIFS('Contribution Log'!$A$2:$A$601,">="&$C$5,'Contribution Log'!$A$2:$A$601,"<="&$C$6,'Contribution Log'!$C$2:$C$601,Lists!$A$7) -> 0 | D25: =COUNTIFS('Contribution Log'!$A$2:$A$601,">="&$C$5,'Contribution Log'!$A$2:$A$601,"<="&$C$6,'Contribution Log'!$D$2:$D$601,Lists!$A$7) -> 0 | E25: =SUMPRODUCT((COUNTIFS('Contribution Log'!$A$2:$A$601,">="&$C$5,'Contribution Log'!$A$2:$A$601,"<="&$C$6,'Contribution Log'!$C$2:$C$601,Lists!$A$7,'Contribution Log'!$J$2:$J$601,Lists!$K$3:$K$61,'Contribution Log'!$Q$2:$Q$601,"Yes - story complete")>0)*1) -> 0
